Workbook
Name _Hlk175215188: 'MR13 1'!#REF!

Sheet ZLP 1
V1: List Price Sheet 6ZL-V
U2: 46143
C3: AFC COST | D3: 35% Margin | E3: 30% Margin | F3: 25% Margin | V3: Section 6
V4: Product Bulletin 6 ZLINE
B6: The Z-Line Series ZL
C8: 1 | N8: 2
B9: PART | C9: STANDARD | D9: LIST | E9: Multiplier | J9: CARTON | K9: CARTON | M9: PART | N9: STANDARD | O9: LIST | P9: Multiplier | U9: CARTON | V9: CARTON
B10: NUMBER | C10: SIZES | D10: PRICE | E10: 0.4 | F10: 35% Margin | G10: 30% Margin | H10: 25% Margin | J10: QUANTITY | K10: WEIGHT | M10: NUMBER | N10: SIZES | O10: PRICE | P10: 0.38 | Q10: 35% Margin | R10: 30% Margin | S10: 25% Margin | U10: QUANTITY | V10: WEIGHT
B11: ZLP10101 | C11: 10x10x1 | D11: 6.85 | E11: =D11*$E$10 -> 2.74 | F11: =(E11/0.65)+0.3 -> 4.5153846 | G11: =(E11/0.7)+0.3 -> 4.2142857 | H11: =(E11/0.75)+0.3 -> 3.9533333 | I11: =(E11/0.8)+0.3 -> 3.725 | J11: 12 | K11: 4 LB. | M11: ZLP10202 | N11: 10x20x2 | O11: 7.52 | P11: =O11*$P$10 -> 2.8576 | Q11: =(P11/0.65)+0.3 -> 4.6963077 | R11: =(P11/0.7)+0.3 -> 4.3822857 | S11: =(P11/0.75)+0.3 -> 4.1101333 | T11: =(P11/0.8)+0.3 -> 3.872 | U11: 12 | V11: 9 LB.
B12: ZLP10201 | C12: 10x20x1 | D12: 7.24 | E12: =D12*$E$10 -> 2.896 | F12: =(E12/0.65)+0.3 -> 4.7553846 | G12: =(E12/0.7)+0.3 -> 4.4371429 | H12: =(E12/0.75)+0.3 -> 4.1613333 | I12: =(E12/0.8)+0.3 -> 3.92 | J12: 12 | K12: 6 LB. | M12: ZLP12122 | N12: 12x12x2 | O12: 10.07 | P12: =O12*$P$10 -> 3.8266 | Q12: =(P12/0.65)+0.3 -> 6.1870769 | R12: =(P12/0.7)+0.3 -> 5.7665714 | S12: =(P12/0.75)+0.3 -> 5.4021333 | T12: =(P12/0.8)+0.3 -> 5.08325 | U12: 12 | V12: 8 LB.
B13: ZLP10241 | C13: 10x24x1 | D13: 14.24 | E13: =D13*$E$10 -> 5.696 | F13: =(E13/0.65)+0.3 -> 9.0630769 | G13: =(E13/0.7)+0.3 -> 8.4371429 | H13: =(E13/0.75)+0.3 -> 7.8946667 | I13: =(E13/0.8)+0.3 -> 7.42 | J13: 12 | K13: 6 LB. | M13: ZLP12202 | N13: 12x20x2 | O13: 8.02 | P13: =O13*$P$10 -> 3.0476 | Q13: =(P13/0.65)+0.3 -> 4.9886154 | R13: =(P13/0.7)+0.3 -> 4.6537143 | S13: =(P13/0.75)+0.3 -> 4.3634667 | T13: =(P13/0.8)+0.3 -> 4.1095 | U13: 12 | V13: 10 LB.
B14: ZLP10301 | C14: 10x30x1 | D14: 14.62 | E14: =D14*$E$10 -> 5.848 | F14: =(E14/0.65)+0.3 -> 9.2969231 | G14: =(E14/0.7)+0.3 -> 8.6542857 | H14: =(E14/0.75)+0.3 -> 8.0973333 | I14: =(E14/0.8)+0.3 -> 7.61 | J14: 12 | K14: 7 LB. | M14: ZLP12242 | N14: 12x24x2 | O14: 7.74 | P14: =O14*$P$10 -> 2.9412 | Q14: =(P14/0.65)+0.3 -> 4.8249231 | R14: =(P14/0.7)+0.3 -> 4.5017143 | S14: =(P14/0.75)+0.3 -> 4.2216 | T14: =(P14/0.8)+0.3 -> 3.9765 | U14: 12 | V14: 9 LB.
B15: ZLP12121 | C15: 12x12x1 | D15: 8.79 | E15: =D15*$E$10 -> 3.516 | F15: =(E15/0.65)+0.3 -> 5.7092308 | G15: =(E15/0.7)+0.3 -> 5.3228571 | H15: =(E15/0.75)+0.3 -> 4.988 | I15: =(E15/0.8)+0.3 -> 4.695 | J15: 12 | K15: 5 LB. | M15: ZLP14202 | N15: 14x20x2 | O15: 8.24 | P15: =O15*$P$10 -> 3.1312 | Q15: =(P15/0.65)+0.3 -> 5.1172308 | R15: =(P15/0.7)+0.3 -> 4.7731429 | S15: =(P15/0.75)+0.3 -> 4.4749333 | T15: =(P15/0.8)+0.3 -> 4.214 | U15: 12 | V15: 9 LB.
B16: ZLP12201 | C16: 12x20x1 | D16: 7.44 | E16: =D16*$E$10 -> 2.976 | F16: =(E16/0.65)+0.3 -> 4.8784615 | G16: =(E16/0.7)+0.3 -> 4.5514286 | H16: =(E16/0.75)+0.3 -> 4.268 | I16: =(E16/0.8)+0.3 -> 4.02 | J16: 12 | K16: 7 LB. | M16: ZLP14252 | N16: 14x25x2 | O16: 9.09 | P16: =O16*$P$10 -> 3.4542 | Q16: =(P16/0.65)+0.3 -> 5.6141538 | R16: =(P16/0.7)+0.3 -> 5.2345714 | S16: =(P16/0.75)+0.3 -> 4.9056 | T16: =(P16/0.8)+0.3 -> 4.61775 | U16: 12 | V16: 11 LB.
B17: ZLP12241 | C17: 12x24x1 | D17: 7.24 | E17: =D17*$E$10 -> 2.896 | F17: =(E17/0.65)+0.3 -> 4.7553846 | G17: =(E17/0.7)+0.3 -> 4.4371429 | H17: =(E17/0.75)+0.3 -> 4.1613333 | I17: =(E17/0.8)+0.3 -> 3.92 | J17: 12 | K17: 6 LB. | M17: ZLP15202 | N17: 15x20x2 | O17: 8.24 | P17: =O17*$P$10 -> 3.1312 | Q17: =(P17/0.65)+0.3 -> 5.1172308 | R17: =(P17/0.7)+0.3 -> 4.7731429 | S17: =(P17/0.75)+0.3 -> 4.4749333 | T17: =(P17/0.8)+0.3 -> 4.214 | U17: 12 | V17: 9 LB.
B18: ZLP12251 | C18: 12x25x1 | D18: 7.74 | E18: =D18*$E$10 -> 3.096 | F18: =(E18/0.65)+0.3 -> 5.0630769 | G18: =(E18/0.7)+0.3 -> 4.7228571 | H18: =(E18/0.75)+0.3 -> 4.428 | I18: =(E18/0.8)+0.3 -> 4.17 | J18: 12 | K18: 6 LB. | M18: ZLP16162 | N18: 16x16x2 | O18: 10.56 | P18: =O18*$P$10 -> 4.0128 | Q18: =(P18/0.65)+0.3 -> 6.4735385 | R18: =(P18/0.7)+0.3 -> 6.0325714 | S18: =(P18/0.75)+0.3 -> 5.6504 | T18: =(P18/0.8)+0.3 -> 5.316 | U18: 12 | V18: 10 LB.
B19: ZLP12301 | C19: 12x30x1 | D19: 14.62 | E19: =D19*$E$10 -> 5.848 | F19: =(E19/0.65)+0.3 -> 9.2969231 | G19: =(E19/0.7)+0.3 -> 8.6542857 | H19: =(E19/0.75)+0.3 -> 8.0973333 | I19: =(E19/0.8)+0.3 -> 7.61 | J19: 12 | K19: 7 LB. | M19: ZLP16202 | N19: 16x20x2 | O19: 7.76 | P19: =O19*$P$10 -> 2.9488 | Q19: =(P19/0.65)+0.3 -> 4.8366154 | R19: =(P19/0.7)+0.3 -> 4.5125714 | S19: =(P19/0.75)+0.3 -> 4.2317333 | T19: =(P19/0.8)+0.3 -> 3.986 | U19: 12 | V19: 10 LB.
B20: ZLP14141 | C20: 14x14x1 | D20: 10.43 | E20: =D20*$E$10 -> 4.172 | F20: =(E20/0.65)+0.3 -> 6.7184615 | G20: =(E20/0.7)+0.3 -> 6.26 | H20: =(E20/0.75)+0.3 -> 5.8626667 | I20: =(E20/0.8)+0.3 -> 5.515 | J20: 12 | K20: 6 LB. | M20: ZLP16242 | N20: 16x24x2 | O20: 10.41 | P20: =O20*$P$10 -> 3.9558 | Q20: =(P20/0.65)+0.3 -> 6.3858462 | R20: =(P20/0.7)+0.3 -> 5.9511429 | S20: =(P20/0.75)+0.3 -> 5.5744 | T20: =(P20/0.8)+0.3 -> 5.24475 | U20: 12 | V20: 11 LB.
B21: ZLP14201 | C21: 14x20x1 | D21: 7.44 | E21: =D21*$E$10 -> 2.976 | F21: =(E21/0.65)+0.3 -> 4.8784615 | G21: =(E21/0.7)+0.3 -> 4.5514286 | H21: =(E21/0.75)+0.3 -> 4.268 | I21: =(E21/0.8)+0.3 -> 4.02 | J21: 12 | K21: 6 LB. | M21: ZLP16252 | N21: 16x25x2 | O21: 8.84 | P21: =O21*$P$10 -> 3.3592 | Q21: =(P21/0.65)+0.3 -> 5.468 | R21: =(P21/0.7)+0.3 -> 5.0988571 | S21: =(P21/0.75)+0.3 -> 4.7789333 | T21: =(P21/0.8)+0.3 -> 4.499 | U21: 12 | V21: 11 LB.
B22: ZLP14241 | C22: 14x24x1 | D22: 12.12 | E22: =D22*$E$10 -> 4.848 | F22: =(E22/0.65)+0.3 -> 7.7584615 | G22: =(E22/0.7)+0.3 -> 7.2257143 | H22: =(E22/0.75)+0.3 -> 6.764 | I22: =(E22/0.8)+0.3 -> 6.36 | J22: 12 | K22: 7 LB. | M22: ZLP18182 | N22: 18x18x2 | O22: 15.6 | P22: =O22*$P$10 -> 5.928 | Q22: =(P22/0.65)+0.3 -> 9.42 | R22: =(P22/0.7)+0.3 -> 8.7685714 | S22: =(P22/0.75)+0.3 -> 8.204 | T22: =(P22/0.8)+0.3 -> 7.71 | U22: 12 | V22: 11 LB.
... B31: ZLP16301 | C31: 16x30x1 | D31: 15.77 | E31: =D31*$E$10 -> 6.308 | F31: =(E31/0.65)+0.3 -> 10.004615 | G31: =(E31/0.7)+0.3 -> 9.3114286 | H31: =(E31/0.75)+0.3 -> 8.7106667 | I31: =(E31/0.8)+0.3 -> 8.185 | J31: 12 | K31: 9 LB. | M31: ZLP25252 | N31: 25x25x2 | O31: 13.86 | P31: =O31*$P$10 -> 5.2668 | Q31: =(P31/0.65)+0.3 -> 8.4027692 | R31: =(P31/0.7)+0.3 -> 7.824 | S31: =(P31/0.75)+0.3 -> 7.3224 | T31: =(P31/0.8)+0.3 -> 6.8835 | U31: 12 | V31: 20 LB.
B32: ZLP18181 | C32: 18x18x1 | D32: 14.62 | E32: =D32*$E$10 -> 5.848 | F32: =(E32/0.65)+0.3 -> 9.2969231 | G32: =(E32/0.7)+0.3 -> 8.6542857 | H32: =(E32/0.75)+0.3 -> 8.0973333 | I32: =(E32/0.8)+0.3 -> 7.61 | J32: 12 | K32: 8 LB.
B33: ZLP18201 | C33: 18x20x1 | D33: 10.19 | E33: =D33*$E$10 -> 4.076 | F33: =(E33/0.65)+0.3 -> 6.5707692 | G33: =(E33/0.7)+0.3 -> 6.1228571 | H33: =(E33/0.75)+0.3 -> 5.7346667 | I33: =(E33/0.8)+0.3 -> 5.395 | J33: 12 | K33: 8 LB. | N33: 4
B34: ZLP18241 | C34: 18x24x1 | D34: 9.77 | E34: =D34*$E$10 -> 3.908 | F34: =(E34/0.65)+0.3 -> 6.3123077 | G34: =(E34/0.7)+0.3 -> 5.8828571 | H34: =(E34/0.75)+0.3 -> 5.5106667 | I34: =(E34/0.8)+0.3 -> 5.185 | J34: 12 | K34: 8 LB. | M34: PART | N34: STANDARD | O34: LIST | P34: Multiplier | U34: CARTON | V34: CARTON
B35: ZLP18251 | C35: 18x25x1 | D35: 9.52 | E35: =D35*$E$10 -> 3.808 | F35: =(E35/0.65)+0.3 -> 6.1584615 | G35: =(E35/0.7)+0.3 -> 5.74 | H35: =(E35/0.75)+0.3 -> 5.3773333 | I35: =(E35/0.8)+0.3 -> 5.06 | J35: 12 | K35: 11 LB. | M35: NUMBER | N35: SIZES | O35: PRICE | P35: 0.4 | Q35: 35% Margin | R35: 30% Margin | S35: 25% Margin | U35: QUANTITY | V35: WEIGHT
B36: ZLP18301 | C36: 18x30x1 | D36: 17.45 | E36: =D36*$E$10 -> 6.98 | F36: =(E36/0.65)+0.3 -> 11.038462 | G36: =(E36/0.7)+0.3 -> 10.271429 | H36: =(E36/0.75)+0.3 -> 9.6066667 | I36: =(E36/0.8)+0.3 -> 9.025 | J36: 12 | K36: 11 LB. | M36: ZLP12244 | N36: 12x24x4 | O36: 12.13 | P36: =O36*$P$35 -> 4.852 | Q36: =(P36/0.65)+0.3 -> 7.7646154 | R36: =(P36/0.7)+0.3 -> 7.2314286 | S36: =(P36/0.75)+0.3 -> 6.7693333 | U36: 6 | V36: 8 LB.
B37: ZLP20201 | C37: 20x20x1 | D37: 7.95 | E37: =D37*$E$10 -> 3.18 | F37: =(E37/0.65)+0.3 -> 5.1923077 | G37: =(E37/0.7)+0.3 -> 4.8428571 | H37: =(E37/0.75)+0.3 -> 4.54 | I37: =(E37/0.8)+0.3 -> 4.275 | J37: 12 | K37: 7 LB. | M37: ZLP16204 | N37: 16x20x4 | O37: 13.02 | P37: =O37*$P$35 -> 5.208 | Q37: =(P37/0.65)+0.3 -> 8.3123077 | R37: =(P37/0.7)+0.3 -> 7.74 | S37: =(P37/0.75)+0.3 -> 7.244 | U37: 6 | V37: 9 LB.
B38: ZLP20221 | C38: 20x22x1 | D38: 14.62 | E38: =D38*$E$10 -> 5.848 | F38: =(E38/0.65)+0.3 -> 9.2969231 | G38: =(E38/0.7)+0.3 -> 8.6542857 | H38: =(E38/0.75)+0.3 -> 8.0973333 | I38: =(E38/0.8)+0.3 -> 7.61 | J38: 12 | K38: 8 LB. | M38: ZLP16244 | N38: 16x24x4 | O38: 16.96 | P38: =O38*$P$35 -> 6.784 | Q38: =(P38/0.65)+0.3 -> 10.736923 | R38: =(P38/0.7)+0.3 -> 9.9914286 | S38: =(P38/0.75)+0.3 -> 9.3453333 | U38: 6 | V38: 11 LB.
B39: ZLP20241 | C39: 20x24x1 | D39: 9.31 | E39: =D39*$E$10 -> 3.724 | F39: =(E39/0.65)+0.3 -> 6.0292308 | G39: =(E39/0.7)+0.3 -> 5.62 | H39: =(E39/0.75)+0.3 -> 5.2653333 | I39: =(E39/0.8)+0.3 -> 4.955 | J39: 12 | K39: 9 LB. | M39: ZLP16254 | N39: 16x25x4 | O39: 13.99 | P39: =O39*$P$35 -> 5.596 | Q39: =(P39/0.65)+0.3 -> 8.9092308 | R39: =(P39/0.7)+0.3 -> 8.2942857 | S39: =(P39/0.75)+0.3 -> 7.7613333 | U39: 6 | V39: 11 LB.
B40: ZLP20251 | C40: 20x25x1 | D40: 9.09 | E40: =D40*$E$10 -> 3.636 | F40: =(E40/0.65)+0.3 -> 5.8938462 | G40: =(E40/0.7)+0.3 -> 5.4942857 | H40: =(E40/0.75)+0.3 -> 5.148 | I40: =(E40/0.8)+0.3 -> 4.845 | J40: 12 | K40: 9 LB. | M40: ZLP18244 | N40: 18x24x4 | O40: 16.15 | P40: =O40*$P$35 -> 6.46 | Q40: =(P40/0.65)+0.3 -> 10.238462 | R40: =(P40/0.7)+0.3 -> 9.5285714 | S40: =(P40/0.75)+0.3 -> 8.9133333 | U40: 6 | V40: 11 LB.
B41: ZLP20301 | C41: 20x30x1 | D41: 11.85 | E41: =D41*$E$10 -> 4.74 | F41: =(E41/0.65)+0.3 -> 7.5923077 | G41: =(E41/0.7)+0.3 -> 7.0714286 | H41: =(E41/0.75)+0.3 -> 6.62 | I41: =(E41/0.8)+0.3 -> 6.225 | J41: 12 | K41: 10 LB. | M41: ZLP20204 | N41: 20x20x4 | O41: 13.92 | P41: =O41*$P$35 -> 5.568 | Q41: =(P41/0.65)+0.3 -> 8.8661538 | R41: =(P41/0.7)+0.3 -> 8.2542857 | S41: =(P41/0.75)+0.3 -> 7.724 | U41: 6 | V41: 11 LB.
B42: ZLP22221 | C42: 22x22x1 | D42: 16.29 | E42: =D42*$E$10 -> 6.516 | F42: =(E42/0.65)+0.3 -> 10.324615 | G42: =(E42/0.7)+0.3 -> 9.6085714 | H42: =(E42/0.75)+0.3 -> 8.988 | I42: =(E42/0.8)+0.3 -> 8.445 | J42: 12 | K42: 8 LB. | M42: ZLP20244 | N42: 20x24x4 | O42: 16.08 | P42: =O42*$P$35 -> 6.432 | Q42: =(P42/0.65)+0.3 -> 10.195385 | R42: =(P42/0.7)+0.3 -> 9.4885714 | S42: =(P42/0.75)+0.3 -> 8.876 | U42: 6 | V42: 13 LB.
B43: ZLP24241 | C43: 24x24x1 | D43: 10.3 | E43: =D43*$E$10 -> 4.12 | F43: =(E43/0.65)+0.3 -> 6.6384615 | G43: =(E43/0.7)+0.3 -> 6.1857143 | H43: =(E43/0.75)+0.3 -> 5.7933333 | I43: =(E43/0.8)+0.3 -> 5.45 | J43: 12 | K43: 10 LB. | M43: ZLP20254 | N43: 20x25x4 | O43: 15.99 | P43: =O43*$P$35 -> 6.396 | Q43: =(P43/0.65)+0.3 -> 10.14 | R43: =(P43/0.7)+0.3 -> 9.4371429 | S43: =(P43/0.75)+0.3 -> 8.828 | U43: 6 | V43: 13 LB.
B44: ZLP24301 | C44: 24x30x1 | D44: 19.25 | E44: =D44*$E$10 -> 7.7 | F44: =(E44/0.65)+0.3 -> 12.146154 | G44: =(E44/0.7)+0.3 -> 11.3 | H44: =(E44/0.75)+0.3 -> 10.566667 | I44: =(E44/0.8)+0.3 -> 9.925 | J44: 12 | K44: 14 LB. | M44: ZLP24244 | N44: 24x24x4 | O44: 18.29 | P44: =O44*$P$35 -> 7.316 | Q44: =(P44/0.65)+0.3 -> 11.555385 | R44: =(P44/0.7)+0.3 -> 10.751429 | S44: =(P44/0.75)+0.3 -> 10.054667 | U44: 6 | V44: 14 LB.
B45: ZLP25251 | C45: 25x25x1 | D45: 11.55 | E45: =D45*$E$10 -> 4.62 | F45: =(E45/0.65)+0.3 -> 7.4076923 | G45: =(E45/0.7)+0.3 -> 6.9 | H45: =(E45/0.75)+0.3 -> 6.46 | I45: =(E45/0.8)+0.3 -> 6.075 | J45: 12 | K45: 14 LB. | M45: Semi-Standard Sizes | Q45: =(P45/0.65)+0.3 -> 0.3 | R45: =(P45/0.7)+0.3 -> 0.3 | S45: =(P45/0.75)+0.3 -> 0.3
M46: ZLP25294 | N46: 25x29x4 | O46: 23.62 | P46: 23.62 | Q46: =(P46/0.65)+0.3 -> 36.638462 | R46: =(P46/0.7)+0.3 -> 34.042857 | S46: =(P46/0.75)+0.3 -> 31.793333 | U46: 6 | V46: 11 LB.
M47: ZLP28304 | N47: 28x30x4 | O47: 30.91 | P47: 30.91 | Q47: =(P47/0.65)+0.3 -> 47.853846 | R47: =(P47/0.7)+0.3 -> 44.457143 | S47: =(P47/0.75)+0.3 -> 41.513333 | U47: 6 | V47: 22 LB.

Sheet ZLP2
M2: SIZES | N2: H | O2: L | P2: W | Q2: TOTAL | R2: PRICE 1" | S2: PRICE 2" | T2: PRICE 4" | Y2: PRICE 1" | Z2: PRICE 2" | AA2: PRICE 4"
C3: AFC COST | D3: 35% Margin | E3: 30% Margin | F3: 25% Margin | N3: 13 | O3: 27 | P3: 1 | Q3: =N3*O3 -> 351 | R3: =_xlfn.XLOOKUP($N$3*$O$3, $D$11:$D$20, $I$11:$I$20, $I$10, -1) -> 13.599231 | S3: =_xlfn.XLOOKUP(N3*O3, $D$11:$D$20, $S$11:$S$20, $S$10, -1) -> 14.852308 | T3: =_xlfn.XLOOKUP(N3*O3, $D$11:$D$20, $AB$11:$AB$20, $AB$10, -1) -> 29.619231 | U3: 0.35 | Y3: =IF(OR(AND($N$3>28, $O$3>28), $N$3>35, $O$3>35),_xlfn.XLOOKUP(($N$3*$O$3)/2, $D$11:$D$20, $I$11:$I$20, $I$10, -1) * 2,"N/A") -> N/A | Z3: =IF(OR(AND($N$3>28, $O$3>28), $N$3>35, $O$3>35),_xlfn.XLOOKUP(($N$3*$O$3)/2, $D$11:$D$20, $S$11:$S$20, $S$10, -1) * 2,"N/A") -> N/A | AA3: =IF(OR(AND($N$3>28, $O$3>28), $N$3>35, $O$3>35),_xlfn.XLOOKUP(($N$3*$O$3)/2, $D$11:$D$20, $AB$11:$AB$20, $AB$10, -1) * 2,"N/A") -> N/A | AB3: 0.35
Q4: 77 | R4: =_xlfn.XLOOKUP($N$3*$O$3, $D$10:$D$20, $J$10:$J$20, $J$10, -1) -> 12.649286 | S4: =_xlfn.XLOOKUP($N$3*$O$3, $D$10:$D$20, $T$10:$T$20, $T$10, -1) -> 13.812857 | T4: =_xlfn.XLOOKUP($N$3*$O$3, $D$10:$D$20, $AC$10:$AC$20, $AC$10, -1) -> 27.525 | U4: 0.3 | Y4: =IF(OR(AND($N$3>28, $O$3>28), $N$3>35, $O$3>35),_xlfn.XLOOKUP(($N$3*$O$3)/2, $D$11:$D$20, $J$11:$J$20, $J$10, -1) * 2,"N/A") -> N/A | Z4: =IF(OR(AND($N$3>28, $O$3>28), $N$3>35, $O$3>35),_xlfn.XLOOKUP(($N$3*$O$3)/2, $D$11:$D$20, $T$11:$T$20, $T$10, -1) * 2,"N/A") -> N/A | AA4: =IF(OR(AND($N$3>28, $O$3>28), $N$3>35, $O$3>35),_xlfn.XLOOKUP(($N$3*$O$3)/2, $D$11:$D$20, $AC$11:$AC$20, $AC$10, -1) * 2,"N/A") -> N/A | AB4: 0.3
C5: The Z-Line Series | R5: =_xlfn.XLOOKUP($N$3*$O$3, $D$10:$D$20, $K$10:$K$20, $K$10, -1) -> 11.826 | S5: =_xlfn.XLOOKUP($N$3*$O$3, $D$10:$D$20, $U$10:$U$20, $U$10, -1) -> 12.912 | T5: =_xlfn.XLOOKUP($N$3*$O$3, $D$10:$D$20, $AD$10:$AD$20, $AD$10, -1) -> 25.71 | U5: 0.25 | Y5: =IF(OR(AND($N$3>28, $O$3>28), $N$3>35, $O$3>35),_xlfn.XLOOKUP(($N$3*$O$3)/2, $D$11:$D$20, $K$11:$K$20, $K$10, -1) * 2,"N/A") -> N/A | Z5: =IF(OR(AND($N$3>28, $O$3>28), $N$3>35, $O$3>35),_xlfn.XLOOKUP(($N$3*$O$3)/2, $D$11:$D$20, $U$11:$U$20, $U$10, -1) * 2,"N/A") -> N/A | AA5: =IF(OR(AND($N$3>28, $O$3>28), $N$3>35, $O$3>35),_xlfn.XLOOKUP(($N$3*$O$3)/2, $D$11:$D$20, $AD$11:$AD$20, $AD$10, -1) * 2,"N/A") -> N/A | AB5: 0.25
C6: MADE-TO-ORDER SIZES | Y6: DOUBLE SIZE PRICING
C7: ZL 1 | M7: ZL 2 | V7: ZL 4
C8: Gross Area | F8: Part | G8: List | H8: Multiplier | M8: Gross Area | P8: Part | Q8: List | R8: Multiplier | V8: Gross Area | Y8: Part | Z8: List | AA8: Multiplier
C9: Square Inches | D9: inches h | E9: inches l | F9: Number | G9: Price | H9: 0.45 | I9: 0.35 | J9: 0.3 | K9: 0.25 | L9: 0.2 | M9: Square Inches | P9: Number | Q9: Price | R9: 0.45 | S9: 0.35 | T9: 0.3 | U9: 0.25 | V9: Square Inches | Y9: Number | Z9: Price | AA9: 0.45 | AB9: 0.35 | AC9: 0.3 | AD9: 0.25
C10: Less than 150 | D10: 0 | E10: 150 | F10: ZLPSP1A | G10: 11.65 | H10: =G10*$H$9 -> 5.2425 | I10: =(H10/0.65)+0.3 -> 8.3653846 | J10: =(H10/0.7)+0.3 -> 7.7892857 | K10: =(H10/0.75)+0.3 -> 7.29 | L10: =(H10/0.8)+0.3 -> 6.853125 | M10: Less than 150 | N10: 0 | O10: 150 | P10: ZLPSP2A | Q10: 13.57 | R10: =Q10*$R$9 -> 6.1065 | S10: =(R10/0.65)+0.3 -> 9.6946154 | T10: =(R10/0.7)+0.3 -> 9.0235714 | U10: =(R10/0.75)+0.3 -> 8.442 | V10: Less than 150 | W10: 0 | X10: 150 | Y10: ZLPSP4A | Z10: 27.05 | AA10: =Z10*$AA$9 -> 12.1725 | AB10: =(AA10/0.65)+0.3 -> 19.026923 | AC10: =(AA10/0.7)+0.3 -> 17.689286 | AD10: =(AA10/0.75)+0.3 -> 16.53 | AE10: =(AA10/0.8)+0.3 -> 15.515625
C11: 150-199 | D11: 150 | E11: 199 | F11: ZLPSP1B | G11: 13.79 | H11: =G11*$H$9 -> 6.2055 | I11: =(H11/0.65)+0.3 -> 9.8469231 | J11: =(H11/0.7)+0.3 -> 9.165 | K11: =(H11/0.75)+0.3 -> 8.574 | L11: =(H11/0.8)+0.3 -> 8.056875 | M11: 150-199 | N11: 150 | O11: 199 | P11: ZLPSP2B | Q11: 15.08 | R11: =Q11*$R$9 -> 6.786 | S11: =(R11/0.65)+0.3 -> 10.74 | T11: =(R11/0.7)+0.3 -> 9.9942857 | U11: =(R11/0.75)+0.3 -> 9.348 | V11: 150-199 | W11: 150 | X11: 199 | Y11: ZLPSP4B | Z11: 30.56 | AA11: =Z11*$AA$9 -> 13.752 | AB11: =(AA11/0.65)+0.3 -> 21.456923 | AC11: =(AA11/0.7)+0.3 -> 19.945714 | AD11: =(AA11/0.75)+0.3 -> 18.636
C12: 200-249 | D12: 200 | E12: 249 | F12: ZLPSP1C | G12: 15.47 | H12: =G12*$H$9 -> 6.9615 | I12: =(H12/0.65)+0.3 -> 11.01 | J12: =(H12/0.7)+0.3 -> 10.245 | K12: =(H12/0.75)+0.3 -> 9.582 | L12: =(H12/0.8)+0.3 -> 9.001875 | M12: 200-249 | N12: 200 | O12: 249 | P12: ZLPSP2C | Q12: 16.95 | R12: =Q12*$R$9 -> 7.6275 | S12: =(R12/0.65)+0.3 -> 12.034615 | T12: =(R12/0.7)+0.3 -> 11.196429 | U12: =(R12/0.75)+0.3 -> 10.47 | V12: 200-249 | W12: 200 | X12: 249 | Y12: ZLPSP4C | Z12: 34.09 | AA12: =Z12*$AA$9 -> 15.3405 | AB12: =(AA12/0.65)+0.3 -> 23.900769 | AC12: =(AA12/0.7)+0.3 -> 22.215 | AD12: =(AA12/0.75)+0.3 -> 20.754
C13: 250-299 | D13: 250 | E13: 299 | F13: ZLPSP1D | G13: 17.07 | H13: =G13*$H$9 -> 7.6815 | I13: =(H13/0.65)+0.3 -> 12.117692 | J13: =(H13/0.7)+0.3 -> 11.273571 | K13: =(H13/0.75)+0.3 -> 10.542 | L13: =(H13/0.8)+0.3 -> 9.901875 | M13: 250-299 | N13: 250 | O13: 299 | P13: ZLPSP2D | Q13: 18.68 | R13: =Q13*$R$9 -> 8.406 | S13: =(R13/0.65)+0.3 -> 13.232308 | T13: =(R13/0.7)+0.3 -> 12.308571 | U13: =(R13/0.75)+0.3 -> 11.508 | V13: 250-299 | W13: 250 | X13: 299 | Y13: ZLPSP4D | Z13: 37.57 | AA13: =Z13*$AA$9 -> 16.9065 | AB13: =(AA13/0.65)+0.3 -> 26.31 | AC13: =(AA13/0.7)+0.3 -> 24.452143 | AD13: =(AA13/0.75)+0.3 -> 22.842
C14: 300-399 | D14: 300 | E14: 399 | F14: ZLPSP1E | G14: 19.21 | H14: =G14*$H$9 -> 8.6445 | I14: =(H14/0.65)+0.3 -> 13.599231 | J14: =(H14/0.7)+0.3 -> 12.649286 | K14: =(H14/0.75)+0.3 -> 11.826 | L14: =(H14/0.8)+0.3 -> 11.105625 | M14: 300-399 | N14: 300 | O14: 399 | P14: ZLPSP2E | Q14: 21.02 | R14: =Q14*$R$9 -> 9.459 | S14: =(R14/0.65)+0.3 -> 14.852308 | T14: =(R14/0.7)+0.3 -> 13.812857 | U14: =(R14/0.75)+0.3 -> 12.912 | V14: 300-399 | W14: 300 | X14: 399 | Y14: ZLPSP4E | Z14: 42.35 | AA14: =Z14*$AA$9 -> 19.0575 | AB14: =(AA14/0.65)+0.3 -> 29.619231 | AC14: =(AA14/0.7)+0.3 -> 27.525 | AD14: =(AA14/0.75)+0.3 -> 25.71
C15: 400-499 | D15: 400 | E15: 499 | F15: ZLPSP1F | G15: 21.39 | H15: =G15*$H$9 -> 9.6255 | I15: =(H15/0.65)+0.3 -> 15.108462 | J15: =(H15/0.7)+0.3 -> 14.050714 | K15: =(H15/0.75)+0.3 -> 13.134 | L15: =(H15/0.8)+0.3 -> 12.331875 | M15: 400-499 | N15: 400 | O15: 499 | P15: ZLPSP2F | Q15: 23.38 | R15: =Q15*$R$9 -> 10.521 | S15: =(R15/0.65)+0.3 -> 16.486154 | T15: =(R15/0.7)+0.3 -> 15.33 | U15: =(R15/0.75)+0.3 -> 14.328 | V15: 400-499 | W15: 400 | X15: 499 | Y15: ZLPSP4F | Z15: 47 | AA15: =Z15*$AA$9 -> 21.15 | AB15: =(AA15/0.65)+0.3 -> 32.838462 | AC15: =(AA15/0.7)+0.3 -> 30.514286 | AD15: =(AA15/0.75)+0.3 -> 28.5
C16: 500-599 | D16: 500 | E16: 599 | F16: ZLPSP1G | G16: 22.95 | H16: =G16*$H$9 -> 10.3275 | I16: =(H16/0.65)+0.3 -> 16.188462 | J16: =(H16/0.7)+0.3 -> 15.053571 | K16: =(H16/0.75)+0.3 -> 14.07 | L16: =(H16/0.8)+0.3 -> 13.209375 | M16: 500-599 | N16: 500 | O16: 599 | P16: ZLPSP2G | Q16: 25.11 | R16: =Q16*$R$9 -> 11.2995 | S16: =(R16/0.65)+0.3 -> 17.683846 | T16: =(R16/0.7)+0.3 -> 16.442143 | U16: =(R16/0.75)+0.3 -> 15.366 | V16: 500-599 | W16: 500 | X16: 599 | Y16: ZLPSP4G | Z16: 50.5 | AA16: =Z16*$AA$9 -> 22.725 | AB16: =(AA16/0.65)+0.3 -> 35.261538 | AC16: =(AA16/0.7)+0.3 -> 32.764286 | AD16: =(AA16/0.75)+0.3 -> 30.6
C17: 600-699 | D17: 600 | E17: 699 | F17: ZLPSP1H | G17: 24.72 | H17: =G17*$H$9 -> 11.124 | I17: =(H17/0.65)+0.3 -> 17.413846 | J17: =(H17/0.7)+0.3 -> 16.191429 | K17: =(H17/0.75)+0.3 -> 15.132 | L17: =(H17/0.8)+0.3 -> 14.205 | M17: 600-699 | N17: 600 | O17: 699 | P17: ZLPSP2H | Q17: 27.02 | R17: =Q17*$R$9 -> 12.159 | S17: =(R17/0.65)+0.3 -> 19.006154 | T17: =(R17/0.7)+0.3 -> 17.67 | U17: =(R17/0.75)+0.3 -> 16.512 | V17: 600-699 | W17: 600 | X17: 699 | Y17: ZLPSP4H | Z17: 54.01 | AA17: =Z17*$AA$9 -> 24.3045 | AB17: =(AA17/0.65)+0.3 -> 37.691538 | AC17: =(AA17/0.7)+0.3 -> 35.020714 | AD17: =(AA17/0.75)+0.3 -> 32.706
C18: 700-799 | D18: 700 | E18: 799 | F18: ZLPSP1I | G18: 26.12 | H18: =G18*$H$9 -> 11.754 | I18: =(H18/0.65)+0.3 -> 18.383077 | J18: =(H18/0.7)+0.3 -> 17.091429 | K18: =(H18/0.75)+0.3 -> 15.972 | L18: =(H18/0.8)+0.3 -> 14.9925 | M18: 700-799 | N18: 700 | O18: 799 | P18: ZLPSP2I | Q18: 28.57 | R18: =Q18*$R$9 -> 12.8565 | S18: =(R18/0.65)+0.3 -> 20.079231 | T18: =(R18/0.7)+0.3 -> 18.666429 | U18: =(R18/0.75)+0.3 -> 17.442 | V18: 700-799 | W18: 700 | X18: 799 | Y18: ZLPSP4I | Z18: 58.33 | AA18: =Z18*$AA$9 -> 26.2485 | AB18: =(AA18/0.65)+0.3 -> 40.682308 | AC18: =(AA18/0.7)+0.3 -> 37.797857 | AD18: =(AA18/0.75)+0.3 -> 35.298
C19: 800-899 | D19: 800 | E19: 899 | F19: ZLPSP1J | G19: 28.72 | H19: =G19*$H$9 -> 12.924 | I19: =(H19/0.65)+0.3 -> 20.183077 | J19: =(H19/0.7)+0.3 -> 18.762857 | K19: =(H19/0.75)+0.3 -> 17.532 | L19: =(H19/0.8)+0.3 -> 16.455 | M19: 800-899 | N19: 800 | O19: 899 | P19: ZLPSP2J | Q19: 31.44 | R19: =Q19*$R$9 -> 14.148 | S19: =(R19/0.65)+0.3 -> 22.066154 | T19: =(R19/0.7)+0.3 -> 20.511429 | U19: =(R19/0.75)+0.3 -> 19.164 | V19: 800-899 | W19: 800 | X19: 899 | Y19: ZLPSP4J | Z19: 66.79 | AA19: =Z19*$AA$9 -> 30.0555 | AB19: =(AA19/0.65)+0.3 -> 46.539231 | AC19: =(AA19/0.7)+0.3 -> 43.236429 | AD19: =(AA19/0.75)+0.3 -> 40.374
C20: 900-999 | D20: 900 | E20: 999 | F20: ZLPSP1K | G20: 31.57 | H20: =G20*$H$9 -> 14.2065 | I20: =(H20/0.65)+0.3 -> 22.156154 | J20: =(H20/0.7)+0.3 -> 20.595 | K20: =(H20/0.75)+0.3 -> 19.242 | L20: =(H20/0.8)+0.3 -> 18.058125 | M20: 900-999 | N20: 900 | O20: 999 | P20: ZLPSP2K | Q20: 34.61 | R20: =Q20*$R$9 -> 15.5745 | S20: =(R20/0.65)+0.3 -> 24.260769 | T20: =(R20/0.7)+0.3 -> 22.549286 | U20: =(R20/0.75)+0.3 -> 21.066 | V20: 900-999 | W20: 900 | X20: 999 | Y20: ZLPSP4K | Z20: 73.46 | AA20: =Z20*$AA$9 -> 33.057 | AB20: =(AA20/0.65)+0.3 -> 51.156923 | AC20: =(AA20/0.7)+0.3 -> 47.524286 | AD20: =(AA20/0.75)+0.3 -> 44.376
C22: * MINIMUM: | P22: * DOUBLE SIZE: Z-Line ZL pleated filters
P23: If both dimensions are larger that 28, or if either dimension is larger than 35, it is considered a double size filter.
C24: 12 Per size; Less than 12 per size add +40% to each filter. | P24: To figure the price on a double size ZL, calculate 1/2 of the square inches for the desired size and then double the list price. The maximum length dimension is 96.
C25: Made to order filters are bulk packed.
C26: * The minimum dimensions of a special size is 4 x 4.
C28: * OPTIONS: For higher efficiency media use the following to calculate list price: | P28: * DOUBLE SIZE: Z-Line Optional 65%, 85% & 95% pleated filters.
P29: Optional Made to Order 65%, 85% & 95% filters are if both dimensions are larger than 24 3/4, or if either dimension is larger than 35 it is considered a double size filter. To figure the price on a double size size optional efficiency, calculate 1/2 of the square inches for the desired size and double the list price.
C30: a) 65% Filters: take list price x 2.75 for standard or special sizes.
C31: b) 85% Filters: take list price x 4.35 for standard or special sizes. | P31: *Note. Insert sizes in their appropiate size cells, use the result based on the depth (width) inches
C32: c) 95% Filters: take list price x 4.75 for standard or special sizes.
Q41: 83280.26 | R41: 6940.0217 | T41: 83280.26 | U41: 6940.0217 | AA41: 83280.26 | AB41: 20820.065
Q42: =Q41-R41 -> 76340.238 | R42: 6940.0217 | T42: =T41-U41 -> 76340.238 | U42: 6940.0217 | AA42: =AA41-AB41 -> 62460.195 | AB42: 20820.065
Q43: =Q42-R42 -> 69400.217 | R43: 6940.0217 | T43: =T42-U42 -> 69400.217 | U43: 6940.0217 | AA43: =AA42-AB42 -> 41640.13 | AB43: 20820.065
Q44: =Q43-R43 -> 62460.195 | R44: 6940.0217 | T44: =T43-U43 -> 62460.195 | U44: 6940.0217 | AA44: =AA43-AB43 -> 20820.065 | AB44: 20820.065
Q45: =Q44-R44 -> 55520.173 | R45: 6940.0217 | T45: =T44-U44 -> 55520.173 | U45: 6940.0217
Q46: =Q45-R45 -> 48580.152 | R46: 6940.0217 | T46: =T45-U45 -> 48580.152 | U46: 6940.0217 | AA46: cent
Q47: =Q46-R46 -> 41640.13 | R47: 6940.0217 | T47: =T46-U46 -> 41640.13 | U47: 6940.0217 | AA47: 78677.14 | AB47: 19669.285
Q48: =Q47-R47 -> 34700.108 | R48: 6940.0217 | T48: =T47-U47 -> 34700.108 | U48: 6940.0217 | AA48: =AA47-AB47 -> 59007.855 | AB48: 19669.285
Q49: =Q48-R48 -> 27760.087 | R49: 6940.0217 | T49: =T48-U48 -> 27760.087 | U49: 6940.0217 | AA49: =AA48-AB48 -> 39338.57 | AB49: 19669.285
Q50: =Q49-R49 -> 20820.065 | R50: 6940.0217 | T50: =T49-U49 -> 20820.065 | U50: 6940.0217 | AA50: =AA49-AB49 -> 19669.285 | AB50: 19669.285
Q51: =Q50-R50 -> 13880.043 | R51: 6940.0217 | T51: =T50-U50 -> 13880.043 | U51: 6940.0217
...

Sheet HVP1
V1: List Price Sheet 6HV-W
P2: 46143
C3: AFC COST | D3: 35% Margin | E3: 30% Margin | F3: 25% Margin | V3: Section 6
V4: Product Bulletin 6 ZLINE
B6: The Z-Line Series HV
B8: PART # | C8: 1 STANDARD | D8: LIST | E8: Multiplier | J8: CTN | K8: CTN | M8: PART # | N8: 2 STANDARD | O8: LIST | P8: Multiplier | U8: CTN | V8: CTN
C9: SIZES | D9: PRICE | E9: 0.34 | F9: 35% Margin | G9: 30% Margin | H9: 25% Margin | J9: QTY | K9: WT | N9: SIZES | O9: PRICE | P9: 0.34 | Q9: 35% Margin | R9: 30% Margin | S9: 25% Margin | T9: 20% Margin | U9: QTY | V9: WT
B10: HVP10101 | C10: 10x10x1 | D10: 9.09 | E10: =D10*$E$9 -> 3.0906 | F10: =(E10/0.65)+0.3 -> 5.0547692 | G10: =(E10/0.7)+0.3 -> 4.7151429 | H10: =(E10/0.75)+0.3 -> 4.4208 | I10: =(E10/0.8)+0.3 -> 4.16325 | J10: 12 | K10: 5 LB. | M10: HVP10202 | N10: 10x20x2 | O10: 11.38 | P10: =O10*$P$9 -> 3.8692 | Q10: =(P10/0.65)+0.3 -> 6.2526154 | R10: =(P10/0.7)+0.3 -> 5.8274286 | S10: =(P10/0.75)+0.3 -> 5.4589333 | T10: =(P10/0.8)+0.3 -> 5.1365 | U10: 12 | V10: 10 LB.
B11: HVP10201 | C11: 10x20x1 | D11: 9.58 | E11: =D11*$E$9 -> 3.2572 | F11: =(E11/0.65)+0.3 -> 5.3110769 | G11: =(E11/0.7)+0.3 -> 4.9531429 | H11: =(E11/0.75)+0.3 -> 4.6429333 | I11: =(E11/0.8)+0.3 -> 4.3715 | J11: 12 | K11: 7 LB. | M11: HVP12122 | N11: 12x12x2 | O11: 11.87 | P11: =O11*$P$9 -> 4.0358 | Q11: =(P11/0.65)+0.3 -> 6.5089231 | R11: =(P11/0.7)+0.3 -> 6.0654286 | S11: =(P11/0.75)+0.3 -> 5.6810667 | T11: =(P11/0.8)+0.3 -> 5.34475 | U11: 12 | V11: 9 LB.
B12: HVP10241 | C12: 10x24x1 | D12: 16.36 | E12: =D12*$E$9 -> 5.5624 | F12: =(E12/0.65)+0.3 -> 8.8575385 | G12: =(E12/0.7)+0.3 -> 8.2462857 | H12: =(E12/0.75)+0.3 -> 7.7165333 | I12: =(E12/0.8)+0.3 -> 7.253 | J12: 12 | K12: 8 LB. | M12: HVP12202 | N12: 12x20x2 | O12: 12.06 | P12: =O12*$P$9 -> 4.1004 | Q12: =(P12/0.65)+0.3 -> 6.6083077 | R12: =(P12/0.7)+0.3 -> 6.1577143 | S12: =(P12/0.75)+0.3 -> 5.7672 | T12: =(P12/0.8)+0.3 -> 5.4255 | U12: 12 | V12: 11 LB.
B13: HVP10301 | C13: 10x30x1 | D13: 16.73 | E13: =D13*$E$9 -> 5.6882 | F13: =(E13/0.65)+0.3 -> 9.0510769 | G13: =(E13/0.7)+0.3 -> 8.426 | H13: =(E13/0.75)+0.3 -> 7.8842667 | I13: =(E13/0.8)+0.3 -> 7.41025 | J13: 12 | K13: 8 LB. | M13: HVP12242 | N13: 12x24x2 | O13: 11.35 | P13: =O13*$P$9 -> 3.859 | Q13: =(P13/0.65)+0.3 -> 6.2369231 | R13: =(P13/0.7)+0.3 -> 5.8128571 | S13: =(P13/0.75)+0.3 -> 5.4453333 | T13: =(P13/0.8)+0.3 -> 5.12375 | U13: 12 | V13: 10 LB.
B14: HVP12121 | C14: 12x12x1 | D14: 11.62 | E14: =D14*$E$9 -> 3.9508 | F14: =(E14/0.65)+0.3 -> 6.3781538 | G14: =(E14/0.7)+0.3 -> 5.944 | H14: =(E14/0.75)+0.3 -> 5.5677333 | I14: =(E14/0.8)+0.3 -> 5.2385 | J14: 12 | K14: 5 LB. | M14: HVP14202 | N14: 14x20x2 | O14: 11.55 | P14: =O14*$P$9 -> 3.927 | Q14: =(P14/0.65)+0.3 -> 6.3415385 | R14: =(P14/0.7)+0.3 -> 5.91 | S14: =(P14/0.75)+0.3 -> 5.536 | T14: =(P14/0.8)+0.3 -> 5.20875 | U14: 12 | V14: 10 LB.
B15: HVP12201 | C15: 12x20x1 | D15: 9.83 | E15: =D15*$E$9 -> 3.3422 | F15: =(E15/0.65)+0.3 -> 5.4418462 | G15: =(E15/0.7)+0.3 -> 5.0745714 | H15: =(E15/0.75)+0.3 -> 4.7562667 | I15: =(E15/0.8)+0.3 -> 4.47775 | J15: 12 | K15: 8 LB. | M15: HVP14252 | N15: 14x25x2 | O15: 12.64 | P15: =O15*$P$9 -> 4.2976 | Q15: =(P15/0.65)+0.3 -> 6.9116923 | R15: =(P15/0.7)+0.3 -> 6.4394286 | S15: =(P15/0.75)+0.3 -> 6.0301333 | T15: =(P15/0.8)+0.3 -> 5.672 | U15: 12 | V15: 13 LB.
B16: HVP12241 | C16: 12x24x1 | D16: 10.08 | E16: =D16*$E$9 -> 3.4272 | F16: =(E16/0.65)+0.3 -> 5.5726154 | G16: =(E16/0.7)+0.3 -> 5.196 | H16: =(E16/0.75)+0.3 -> 4.8696 | I16: =(E16/0.8)+0.3 -> 4.584 | J16: 12 | K16: 7 LB. | M16: HVP15202 | N16: 15x20x2 | O16: 11.95 | P16: =O16*$P$9 -> 4.063 | Q16: =(P16/0.65)+0.3 -> 6.5507692 | R16: =(P16/0.7)+0.3 -> 6.1042857 | S16: =(P16/0.75)+0.3 -> 5.7173333 | T16: =(P16/0.8)+0.3 -> 5.37875 | U16: 12 | V16: 11 LB.
B17: HVP12251 | C17: 12x25x1 | D17: 10.79 | E17: =D17*$E$9 -> 3.6686 | F17: =(E17/0.65)+0.3 -> 5.944 | G17: =(E17/0.7)+0.3 -> 5.5408571 | H17: =(E17/0.75)+0.3 -> 5.1914667 | I17: =(E17/0.8)+0.3 -> 4.88575 | J17: 12 | K17: 7 LB. | M17: HVP16162 | N17: 16x16x2 | O17: 15.38 | P17: =O17*$P$9 -> 5.2292 | Q17: =(P17/0.65)+0.3 -> 8.3449231 | R17: =(P17/0.7)+0.3 -> 7.7702857 | S17: =(P17/0.75)+0.3 -> 7.2722667 | T17: =(P17/0.8)+0.3 -> 6.8365 | U17: 12 | V17: 12 LB.
B18: HVP12301 | C18: 12x30x1 | D18: 16.73 | E18: =D18*$E$9 -> 5.6882 | F18: =(E18/0.65)+0.3 -> 9.0510769 | G18: =(E18/0.7)+0.3 -> 8.426 | H18: =(E18/0.75)+0.3 -> 7.8842667 | I18: =(E18/0.8)+0.3 -> 7.41025 | J18: 12 | K18: 8 LB. | M18: HVP16202 | N18: 16x20x2 | O18: 11.48 | P18: =O18*$P$9 -> 3.9032 | Q18: =(P18/0.65)+0.3 -> 6.3049231 | R18: =(P18/0.7)+0.3 -> 5.876 | S18: =(P18/0.75)+0.3 -> 5.5042667 | T18: =(P18/0.8)+0.3 -> 5.179 | U18: 12 | V18: 12 LB.
B19: HVP14141 | C19: 14x14x1 | D19: 12.01 | E19: =D19*$E$9 -> 4.0834 | F19: =(E19/0.65)+0.3 -> 6.5821538 | G19: =(E19/0.7)+0.3 -> 6.1334286 | H19: =(E19/0.75)+0.3 -> 5.7445333 | I19: =(E19/0.8)+0.3 -> 5.40425 | J19: 12 | K19: 6 LB. | M19: HVP16242 | N19: 16x24x2 | O19: 14.71 | P19: =O19*$P$9 -> 5.0014 | Q19: =(P19/0.65)+0.3 -> 7.9944615 | R19: =(P19/0.7)+0.3 -> 7.4448571 | S19: =(P19/0.75)+0.3 -> 6.9685333 | T19: =(P19/0.8)+0.3 -> 6.55175 | U19: 12 | V19: 14 LB.
B20: HVP14201 | C20: 14x20x1 | D20: 10.26 | E20: =D20*$E$9 -> 3.4884 | F20: =(E20/0.65)+0.3 -> 5.6667692 | G20: =(E20/0.7)+0.3 -> 5.2834286 | H20: =(E20/0.75)+0.3 -> 4.9512 | I20: =(E20/0.8)+0.3 -> 4.6605 | J20: 12 | K20: 7 LB. | M20: HVP16252 | N20: 16x25x2 | O20: 13.24 | P20: =O20*$P$9 -> 4.5016 | Q20: =(P20/0.65)+0.3 -> 7.2255385 | R20: =(P20/0.7)+0.3 -> 6.7308571 | S20: =(P20/0.75)+0.3 -> 6.3021333 | T20: =(P20/0.8)+0.3 -> 5.927 | U20: 12 | V20: 14 LB.
B21: HVP14241 | C21: 14x24x1 | D21: 16.61 | E21: =D21*$E$9 -> 5.6474 | F21: =(E21/0.65)+0.3 -> 8.9883077 | G21: =(E21/0.7)+0.3 -> 8.3677143 | H21: =(E21/0.75)+0.3 -> 7.8298667 | I21: =(E21/0.8)+0.3 -> 7.35925 | J21: 12 | K21: 8 LB. | M21: HVP18182 | N21: 18x18x2 | O21: 19.13 | P21: =O21*$P$9 -> 6.5042 | Q21: =(P21/0.65)+0.3 -> 10.306462 | R21: =(P21/0.7)+0.3 -> 9.5917143 | S21: =(P21/0.75)+0.3 -> 8.9722667 | T21: =(P21/0.8)+0.3 -> 8.43025 | U21: 12 | V21: 12 LB.
... B30: HVP16301 | C30: 16x30x1 | D30: 18.08 | E30: =D30*$E$9 -> 6.1472 | F30: =(E30/0.65)+0.3 -> 9.7572308 | G30: =(E30/0.7)+0.3 -> 9.0817143 | H30: =(E30/0.75)+0.3 -> 8.4962667 | I30: =(E30/0.8)+0.3 -> 7.984 | J30: 12 | K30: 9 LB. | M30: HVP25252 | N30: 25x25x2 | O30: 20.79 | P30: =O30*$P$9 -> 7.0686 | Q30: =(P30/0.65)+0.3 -> 11.174769 | R30: =(P30/0.7)+0.3 -> 10.398 | S30: =(P30/0.75)+0.3 -> 9.7248 | T30: =(P30/0.8)+0.3 -> 9.13575 | U30: 12 | V30: 21 LB.
B31: HVP18181 | C31: 18x18x1 | D31: 16.73 | E31: =D31*$E$9 -> 5.6882 | F31: =(E31/0.65)+0.3 -> 9.0510769 | G31: =(E31/0.7)+0.3 -> 8.426 | H31: =(E31/0.75)+0.3 -> 7.8842667 | I31: =(E31/0.8)+0.3 -> 7.41025 | J31: 12 | K31: 7 LB.
B32: HVP18201 | C32: 18x20x1 | D32: 15.3 | E32: =D32*$E$9 -> 5.202 | F32: =(E32/0.65)+0.3 -> 8.3030769 | G32: =(E32/0.7)+0.3 -> 7.7314286 | H32: =(E32/0.75)+0.3 -> 7.236 | I32: =(E32/0.8)+0.3 -> 6.8025 | J32: 12 | K32: 11 LB.
B33: HVP18241 | C33: 18x24x1 | D33: 12.58 | E33: =D33*$E$9 -> 4.2772 | F33: =(E33/0.65)+0.3 -> 6.8803077 | G33: =(E33/0.7)+0.3 -> 6.4102857 | H33: =(E33/0.75)+0.3 -> 6.0029333 | I33: =(E33/0.8)+0.3 -> 5.6465 | J33: 12 | K33: 9 LB. | M33: PART # | N33: 4 STANDARD | O33: LIST | P33: Multiplier | U33: CTN | V33: CTN
B34: HVP18251 | C34: 18x25x1 | D34: 12.57 | E34: =D34*$E$9 -> 4.2738 | F34: =(E34/0.65)+0.3 -> 6.8750769 | G34: =(E34/0.7)+0.3 -> 6.4054286 | H34: =(E34/0.75)+0.3 -> 5.9984 | I34: =(E34/0.8)+0.3 -> 5.64225 | J34: 12 | K34: 12 LB. | N34: SIZES | O34: PRICE | P34: 0.34 | Q34: 35% Margin | R34: 30% Margin | S34: 25% Margin | T34: 20% Margin | U34: QTY | V34: WT
B35: HVP18301 | C35: 18x30x1 | D35: 19.96 | E35: =D35*$E$9 -> 6.7864 | F35: =(E35/0.65)+0.3 -> 10.740615 | G35: =(E35/0.7)+0.3 -> 9.9948571 | H35: =(E35/0.75)+0.3 -> 9.3485333 | I35: =(E35/0.8)+0.3 -> 8.783 | J35: 12 | K35: 9 LB. | M35: HVP12244 | N35: 12x24x4 | O35: 19.73 | P35: =O35*$P$34 -> 6.7082 | Q35: =(P35/0.65)+0.3 -> 10.620308 | R35: =(P35/0.7)+0.3 -> 9.8831429 | S35: =(P35/0.75)+0.3 -> 9.2442667 | T35: =(P35/0.8)+0.3 -> 8.68525 | U35: 6 | V35: 9 LB.
B36: HVP20201 | C36: 20x20x1 | D36: 10.99 | E36: =D36*$E$9 -> 3.7366 | F36: =(E36/0.65)+0.3 -> 6.0486154 | G36: =(E36/0.7)+0.3 -> 5.638 | H36: =(E36/0.75)+0.3 -> 5.2821333 | I36: =(E36/0.8)+0.3 -> 4.97075 | J36: 12 | K36: 8 LB. | M36: HVP16204 | N36: 16x20x4 | O36: 19.71 | P36: =O36*$P$34 -> 6.7014 | Q36: =(P36/0.65)+0.3 -> 10.609846 | R36: =(P36/0.7)+0.3 -> 9.8734286 | S36: =(P36/0.75)+0.3 -> 9.2352 | T36: =(P36/0.8)+0.3 -> 8.67675 | U36: 6 | V36: 10 LB.
B37: HVP20221 | C37: 20x22x1 | D37: 16.73 | E37: =D37*$E$9 -> 5.6882 | F37: =(E37/0.65)+0.3 -> 9.0510769 | G37: =(E37/0.7)+0.3 -> 8.426 | H37: =(E37/0.75)+0.3 -> 7.8842667 | I37: =(E37/0.8)+0.3 -> 7.41025 | J37: 12 | K37: 8 LB. | M37: HVP16254 | N37: 16x25x4 | O37: 22.96 | P37: =O37*$P$34 -> 7.8064 | Q37: =(P37/0.65)+0.3 -> 12.309846 | R37: =(P37/0.7)+0.3 -> 11.452 | S37: =(P37/0.75)+0.3 -> 10.708533 | T37: =(P37/0.8)+0.3 -> 10.058 | U37: 6 | V37: 12 LB.
B38: HVP20241 | C38: 20x24x1 | D38: 12.48 | E38: =D38*$E$9 -> 4.2432 | F38: =(E38/0.65)+0.3 -> 6.828 | G38: =(E38/0.7)+0.3 -> 6.3617143 | H38: =(E38/0.75)+0.3 -> 5.9576 | I38: =(E38/0.8)+0.3 -> 5.604 | J38: 12 | K38: 9 LB. | M38: HVP18244 | N38: 18x24x4 | O38: 25.15 | P38: =O38*$P$34 -> 8.551 | Q38: =(P38/0.65)+0.3 -> 13.455385 | R38: =(P38/0.7)+0.3 -> 12.515714 | S38: =(P38/0.75)+0.3 -> 11.701333 | T38: =(P38/0.8)+0.3 -> 10.98875 | U38: 6 | V38: 13 LB.
B39: HVP20251 | C39: 20x25x1 | D39: 12.21 | E39: =D39*$E$9 -> 4.1514 | F39: =(E39/0.65)+0.3 -> 6.6867692 | G39: =(E39/0.7)+0.3 -> 6.2305714 | H39: =(E39/0.75)+0.3 -> 5.8352 | I39: =(E39/0.8)+0.3 -> 5.48925 | J39: 12 | K39: 9 LB. | M39: HVP20204 | N39: 20x20x4 | O39: 23.51 | P39: =O39*$P$34 -> 7.9934 | Q39: =(P39/0.65)+0.3 -> 12.597538 | R39: =(P39/0.7)+0.3 -> 11.719143 | S39: =(P39/0.75)+0.3 -> 10.957867 | T39: =(P39/0.8)+0.3 -> 10.29175 | U39: 6 | V39: 11 LB.
B40: HVP20301 | C40: 20x30x1 | D40: 16.46 | E40: =D40*$E$9 -> 5.5964 | F40: =(E40/0.65)+0.3 -> 8.9098462 | G40: =(E40/0.7)+0.3 -> 8.2948571 | H40: =(E40/0.75)+0.3 -> 7.7618667 | I40: =(E40/0.8)+0.3 -> 7.2955 | J40: 12 | K40: 10 LB. | M40: HVP20244 | N40: 20x24x4 | O40: 26.57 | P40: =O40*$P$34 -> 9.0338 | Q40: =(P40/0.65)+0.3 -> 14.198154 | R40: =(P40/0.7)+0.3 -> 13.205429 | S40: =(P40/0.75)+0.3 -> 12.345067 | T40: =(P40/0.8)+0.3 -> 11.59225 | U40: 6 | V40: 14 LB.
B41: HVP22221 | C41: 22x22x1 | D41: 18.62 | E41: =D41*$E$9 -> 6.3308 | F41: =(E41/0.65)+0.3 -> 10.039692 | G41: =(E41/0.7)+0.3 -> 9.344 | H41: =(E41/0.75)+0.3 -> 8.7410667 | I41: =(E41/0.8)+0.3 -> 8.2135 | J41: 12 | K41: 8 LB. | M41: HVP20254 | N41: 20x25x4 | O41: 26.16 | P41: =O41*$P$34 -> 8.8944 | Q41: =(P41/0.65)+0.3 -> 13.983692 | R41: =(P41/0.7)+0.3 -> 13.006286 | S41: =(P41/0.75)+0.3 -> 12.1592 | T41: =(P41/0.8)+0.3 -> 11.418 | U41: 6 | V41: 13 LB.
B42: HVP24241 | C42: 24x24x1 | D42: 14.26 | E42: =D42*$E$9 -> 4.8484 | F42: =(E42/0.65)+0.3 -> 7.7590769 | G42: =(E42/0.7)+0.3 -> 7.2262857 | H42: =(E42/0.75)+0.3 -> 6.7645333 | I42: =(E42/0.8)+0.3 -> 6.3605 | J42: 12 | K42: 11 LB. | M42: HVP24244 | N42: 24x24x4 | O42: 29.76 | P42: =O42*$P$34 -> 10.1184 | Q42: =(P42/0.65)+0.3 -> 15.866769 | R42: =(P42/0.7)+0.3 -> 14.754857 | S42: =(P42/0.75)+0.3 -> 13.7912 | T42: =(P42/0.8)+0.3 -> 12.948 | U42: 6 | V42: 16 LB.
B43: HVP24301 | C43: 24x30x1 | D43: 22.06 | E43: =D43*$E$9 -> 7.5004 | F43: =(E43/0.65)+0.3 -> 11.839077 | G43: =(E43/0.7)+0.3 -> 11.014857 | H43: =(E43/0.75)+0.3 -> 10.300533 | I43: =(E43/0.8)+0.3 -> 9.6755 | J43: 12 | K43: 15 LB. | M43: Semi-Std. Sizes
B44: HVP25251 | C44: 25x25x1 | D44: 15.32 | E44: =D44*$E$9 -> 5.2088 | F44: =(E44/0.65)+0.3 -> 8.3135385 | G44: =(E44/0.7)+0.3 -> 7.7411429 | H44: =(E44/0.75)+0.3 -> 7.2450667 | I44: =(E44/0.8)+0.3 -> 6.811 | J44: 12 | K44: 15 LB. | M44: HVP25294 | N44: 25x29x4 | O44: 36.22 | U44: 6 | V44: 12 LB.
N45: (24 1/2x28 1/2) | O45: 0 | P45: 14.49
M46: HVP28304 | N46: 28x30x4 | O46: 47.45 | P46: 18.98 | U46: 6 | V46: 23 LB.
M47: Peripheral header available on: 12x24x4 & 24x24x4;
M48: placed on the air entering side
M49: Add +35% to List Price. Add HDR to the end of
M50: Part Number; minimum of 12 per size.
...

Sheet HVP2
H2: SIZES | I2: H | J2: L | K2: W | L2: TOTAL | M2: PRICE 1" | N2: PRICE 2" | O2: PRICE 4" | R2: PRICE 1" | S2: PRICE 2" | T2: PRICE 4"
C3: AFC COST | D3: 35% Margin | E3: 30% Margin | F3: 25% Margin | I3: 16 | J3: 33 | K3: 1 | L3: =I3*J3 -> 528 | M3: =_xlfn.XLOOKUP($I$3*$J$3, $C$11:$C$21, $H$11:$H$21, $H$11, -1) -> 18.473077 | N3: =_xlfn.XLOOKUP(I3*J3, $C$11:$C$21, $S$11:$S$21, $S$11, -1) -> 21.588462 | O3: =_xlfn.XLOOKUP(I3*J3, $C$24:$C$34, $H$24:$H$34, $H$24, -1) -> 40.772308 | P3: 0.35 | R3: =IF(OR(AND($I$3>28, $J$3>28), $I$3>35, $J$3>35),_xlfn.XLOOKUP(($I$3*$J$3)/2, $C$11:$C$21, $H$11:$H$21, $H$11, -1) * 2,"N/A") -> N/A | S3: =IF(OR(AND($I$3>28, $J$3>28), $I$3>35, $J$3>35),_xlfn.XLOOKUP(($I$3*$J$3)/2, $C$11:$C$21, $S$11:$S$21, $S$11, -1) * 2,"N/A") -> N/A | T3: =IF(OR(AND($I$3>28, $J$3>28), $I$3>35, $J$3>35),_xlfn.XLOOKUP(($I$3*$J$3)/2, $C$11:$C$21, $H$24:$H$34, $H$24, -1) * 2,"N/A") -> N/A | U3: 0.35
M4: =_xlfn.XLOOKUP($I$3*$J$3, $C$11:$C$21, $I$11:$I$21, $I$11, -1) -> 17.175 | N4: =_xlfn.XLOOKUP($I$3*$J$3, $C$11:$C$21, $T$11:$T$21, $T$11, -1) -> 20.067857 | O4: =_xlfn.XLOOKUP($I$3*$J$3, $C$11:$C$21, $I$24:$I$34, $I$24, -1) -> 37.881429 | P4: 0.3 | R4: =IF(OR(AND($I$3>28, $J$3>28), $I$3>35, $J$3>35),_xlfn.XLOOKUP(($I$3*$J$3)/2, $C$11:$C$21, $I$11:$I$21, $I$11, -1) * 2,"N/A") -> N/A | S4: =IF(OR(AND($I$3>28, $J$3>28), $I$3>35, $J$3>35),_xlfn.XLOOKUP(($I$3*$J$3)/2, $C$11:$C$21, $T$11:$T$21, $T$11, -1) * 2,"N/A") -> N/A | T4: =IF(OR(AND($I$3>28, $J$3>28), $I$3>35, $J$3>35),_xlfn.XLOOKUP(($I$3*$J$3)/2, $C$11:$C$21, $I$24:$I$34, $I$24, -1) * 2,"N/A") -> N/A | U4: 0.3
M5: =_xlfn.XLOOKUP($I$3*$J$3, $C$11:$C$21, $J$11:$J$21, $J$11, -1) -> 16.05 | N5: =_xlfn.XLOOKUP($I$3*$J$3, $C$11:$C$21, $U$11:$U$21, $U$11, -1) -> 18.75 | O5: =_xlfn.XLOOKUP($I$3*$J$3, $C$11:$C$21, $J$24:$J$34, $J$24, -1) -> 35.376 | P5: 0.25 | R5: =IF(OR(AND($I$3>28, $J$3>28), $I$3>35, $J$3>35),_xlfn.XLOOKUP(($I$3*$J$3)/2, $C$11:$C$21, $J$11:$J$21, $J$11, -1) * 2,"N/A") -> N/A | S5: =IF(OR(AND($I$3>28, $J$3>28), $I$3>35, $J$3>35),_xlfn.XLOOKUP(($I$3*$J$3)/2, $C$11:$C$21, $U$11:$U$21, $U$11, -1) * 2,"N/A") -> N/A | T5: =IF(OR(AND($I$3>28, $J$3>28), $I$3>35, $J$3>35),_xlfn.XLOOKUP(($I$3*$J$3)/2, $C$11:$C$21, $J$24:$J$34, $J$24, -1) * 2,"N/A") -> N/A | U5: 0.25
B6: The Z-Line Series | R6: DOUBLE SIZE PRICING
B7: MADE-TO-ORDER SIZES
B8: HV 1 | G8: Multiplier
B9: Gross Area | E9: Part | F9: List | G9: 0.45
B10: Square Inches | E10: Number | F10: Price | G10: AFC COST | H10: 35% Margin | I10: 30% Margin | J10: 25% Margin | M10: HV 2 | R10: AFC COST | S10: 35% Margin | T10: 30% Margin | U10: 25% Margin | V10: 20% Margin
B11: Less than 150 | C11: 0 | D11: 150 | E11: HVPSP1A | F11: 13.36 | G11: =F11*$G$9 -> 6.012 | H11: =(G11/0.65)+0.3 -> 9.5492308 | I11: =(G11/0.7)+0.3 -> 8.8885714 | J11: =(G11/0.75)+0.3 -> 8.316 | K11: =(G11/0.8)+0.3 -> 7.815 | M11: Less than 150 | N11: 0 | O11: 150 | P11: HVPSP2A | Q11: 16.03 | R11: =Q11*$G$9 -> 7.2135 | S11: =(R11/0.65)+0.3 -> 11.397692 | T11: =(R11/0.7)+0.3 -> 10.605 | U11: =(R11/0.75)+0.3 -> 9.918 | V11: =(R11/0.8)+0.3 -> 9.316875
B12: 150-199 | C12: 150 | D12: 199 | E12: HVPSP1B | F12: 15.76 | G12: =F12*$G$9 -> 7.092 | H12: =(G12/0.65)+0.3 -> 11.210769 | I12: =(G12/0.7)+0.3 -> 10.431429 | J12: =(G12/0.75)+0.3 -> 9.756 | K12: =(G12/0.8)+0.3 -> 9.165 | M12: 150-199 | N12: {=_xlfn.TEXTSPLIT(M12,"-")} -> 150 | O12: 199 | P12: HVPSP2B | Q12: 18.44 | R12: =Q12*$G$9 -> 8.298 | S12: =(R12/0.65)+0.3 -> 13.066154 | T12: =(R12/0.7)+0.3 -> 12.154286 | U12: =(R12/0.75)+0.3 -> 11.364 | V12: =(R12/0.8)+0.3 -> 10.6725
B13: 200-249 | C13: 200 | D13: 249 | E13: HVPSP1C | F13: 17.77 | G13: =F13*$G$9 -> 7.9965 | H13: =(G13/0.65)+0.3 -> 12.602308 | I13: =(G13/0.7)+0.3 -> 11.723571 | J13: =(G13/0.75)+0.3 -> 10.962 | K13: =(G13/0.8)+0.3 -> 10.295625 | M13: 200-249 | N13: {=_xlfn.TEXTSPLIT(M13,"-")} -> 200 | O13: 249 | P13: HVPSP2C | Q13: 20.8 | R13: =Q13*$G$9 -> 9.36 | S13: =(R13/0.65)+0.3 -> 14.7 | T13: =(R13/0.7)+0.3 -> 13.671429 | U13: =(R13/0.75)+0.3 -> 12.78 | V13: =(R13/0.8)+0.3 -> 12
B14: 250-299 | C14: 250 | D14: 299 | E14: HVPSP1D | F14: 19.6 | G14: =F14*$G$9 -> 8.82 | H14: =(G14/0.65)+0.3 -> 13.869231 | I14: =(G14/0.7)+0.3 -> 12.9 | J14: =(G14/0.75)+0.3 -> 12.06 | K14: =(G14/0.8)+0.3 -> 11.325 | M14: 250-299 | N14: {=_xlfn.TEXTSPLIT(M14,"-")} -> 250 | O14: 299 | P14: HVPSP2D | Q14: 22.9 | R14: =Q14*$G$9 -> 10.305 | S14: =(R14/0.65)+0.3 -> 16.153846 | T14: =(R14/0.7)+0.3 -> 15.021429 | U14: =(R14/0.75)+0.3 -> 14.04 | V14: =(R14/0.8)+0.3 -> 13.18125
B15: 300-399 | C15: 300 | D15: 399 | E15: HVPSP1E | F15: 22.04 | G15: =F15*$G$9 -> 9.918 | H15: =(G15/0.65)+0.3 -> 15.558462 | I15: =(G15/0.7)+0.3 -> 14.468571 | J15: =(G15/0.75)+0.3 -> 13.524 | K15: =(G15/0.8)+0.3 -> 12.6975 | M15: 300-399 | N15: {=_xlfn.TEXTSPLIT(M15,"-")} -> 300 | O15: 399 | P15: HVPSP2E | Q15: 25.8 | R15: =Q15*$G$9 -> 11.61 | S15: =(R15/0.65)+0.3 -> 18.161538 | T15: =(R15/0.7)+0.3 -> 16.885714 | U15: =(R15/0.75)+0.3 -> 15.78 | V15: =(R15/0.8)+0.3 -> 14.8125
B16: 400-499 | C16: 400 | D16: 499 | E16: HVPSP1F | F16: 24.48 | G16: =F16*$G$9 -> 11.016 | H16: =(G16/0.65)+0.3 -> 17.247692 | I16: =(G16/0.7)+0.3 -> 16.037143 | J16: =(G16/0.75)+0.3 -> 14.988 | K16: =(G16/0.8)+0.3 -> 14.07 | M16: 400-499 | N16: {=_xlfn.TEXTSPLIT(M16,"-")} -> 400 | O16: 499 | P16: HVPSP2F | Q16: 28.67 | R16: =Q16*$G$9 -> 12.9015 | S16: =(R16/0.65)+0.3 -> 20.148462 | T16: =(R16/0.7)+0.3 -> 18.730714 | U16: =(R16/0.75)+0.3 -> 17.502 | V16: =(R16/0.8)+0.3 -> 16.426875
B17: 500-599 | C17: 500 | D17: 599 | E17: HVPSP1G | F17: 26.25 | G17: =F17*$G$9 -> 11.8125 | H17: =(G17/0.65)+0.3 -> 18.473077 | I17: =(G17/0.7)+0.3 -> 17.175 | J17: =(G17/0.75)+0.3 -> 16.05 | K17: =(G17/0.8)+0.3 -> 15.065625 | M17: 500-599 | N17: {=_xlfn.TEXTSPLIT(M17,"-")} -> 500 | O17: 599 | P17: HVPSP2G | Q17: 30.75 | R17: =Q17*$G$9 -> 13.8375 | S17: =(R17/0.65)+0.3 -> 21.588462 | T17: =(R17/0.7)+0.3 -> 20.067857 | U17: =(R17/0.75)+0.3 -> 18.75 | V17: =(R17/0.8)+0.3 -> 17.596875
B18: 600-699 | C18: 600 | D18: 699 | E18: HVPSP1H | F18: 28.25 | G18: =F18*$G$9 -> 12.7125 | H18: =(G18/0.65)+0.3 -> 19.857692 | I18: =(G18/0.7)+0.3 -> 18.460714 | J18: =(G18/0.75)+0.3 -> 17.25 | K18: =(G18/0.8)+0.3 -> 16.190625 | M18: 600-699 | N18: {=_xlfn.TEXTSPLIT(M18,"-")} -> 600 | O18: 699 | P18: HVPSP2H | Q18: 33.04 | R18: =Q18*$G$9 -> 14.868 | S18: =(R18/0.65)+0.3 -> 23.173846 | T18: =(R18/0.7)+0.3 -> 21.54 | U18: =(R18/0.75)+0.3 -> 20.124 | V18: =(R18/0.8)+0.3 -> 18.885
B19: 700-799 | C19: 700 | D19: 799 | E19: HVPSP1I | F19: 29.92 | G19: =F19*$G$9 -> 13.464 | H19: =(G19/0.65)+0.3 -> 21.013846 | I19: =(G19/0.7)+0.3 -> 19.534286 | J19: =(G19/0.75)+0.3 -> 18.252 | K19: =(G19/0.8)+0.3 -> 17.13 | M19: 700-799 | N19: {=_xlfn.TEXTSPLIT(M19,"-")} -> 700 | O19: 799 | P19: HVPSP2I | Q19: 34.96 | R19: =Q19*$G$9 -> 15.732 | S19: =(R19/0.65)+0.3 -> 24.503077 | T19: =(R19/0.7)+0.3 -> 22.774286 | U19: =(R19/0.75)+0.3 -> 21.276 | V19: =(R19/0.8)+0.3 -> 19.965
B20: 800-899 | C20: 800 | D20: 899 | E20: HVPSP1J | F20: 32.88 | G20: =F20*$G$9 -> 14.796 | H20: =(G20/0.65)+0.3 -> 23.063077 | I20: =(G20/0.7)+0.3 -> 21.437143 | J20: =(G20/0.75)+0.3 -> 20.028 | K20: =(G20/0.8)+0.3 -> 18.795 | M20: 800-899 | N20: {=_xlfn.TEXTSPLIT(M20,"-")} -> 800 | O20: 899 | P20: HVPSP2J | Q20: 38.48 | R20: =Q20*$G$9 -> 17.316 | S20: =(R20/0.65)+0.3 -> 26.94 | T20: =(R20/0.7)+0.3 -> 25.037143 | U20: =(R20/0.75)+0.3 -> 23.388 | V20: =(R20/0.8)+0.3 -> 21.945
B21: 900-999 | C21: 900 | D21: 999 | E21: HVPSP1K | F21: 36.16 | G21: =F21*$G$9 -> 16.272 | H21: =(G21/0.65)+0.3 -> 25.333846 | I21: =(G21/0.7)+0.3 -> 23.545714 | J21: =(G21/0.75)+0.3 -> 21.996 | K21: =(G21/0.8)+0.3 -> 20.64 | M21: 900-999 | N21: {=_xlfn.TEXTSPLIT(M21,"-")} -> 900 | O21: 999 | P21: HVPSP2K | Q21: 42.29 | R21: =Q21*$G$9 -> 19.0305 | S21: =(R21/0.65)+0.3 -> 29.577692 | T21: =(R21/0.7)+0.3 -> 27.486429 | U21: =(R21/0.75)+0.3 -> 25.674 | V21: =(R21/0.8)+0.3 -> 24.088125
B23: HV 4 | G23: AFC COST | H23: 35% Margin | I23: 30% Margin | J23: 25% Margin
B24: Square Inches | C24: 0 | D24: 150 | E24: HVPSP4A | F24: 31.31 | G24: =F24*$G$9 -> 14.0895 | H24: =(G24/0.65)+0.3 -> 21.976154 | I24: =(G24/0.7)+0.3 -> 20.427857 | J24: =(G24/0.75)+0.3 -> 19.086 | K24: =(G24/0.8)+0.3 -> 17.911875
B25: 150-199 | C25: 150 | D25: 199 | E25: HVPSP4B | F25: 35.38 | G25: =F25*$G$9 -> 15.921 | H25: =(G25/0.65)+0.3 -> 24.793846 | I25: =(G25/0.7)+0.3 -> 23.044286 | J25: =(G25/0.75)+0.3 -> 21.528 | K25: =(G25/0.8)+0.3 -> 20.20125
B26: 200-249 | C26: 200 | D26: 249 | E26: HVPSP4C | F26: 39.43 | G26: =F26*$G$9 -> 17.7435 | H26: =(G26/0.65)+0.3 -> 27.597692 | I26: =(G26/0.7)+0.3 -> 25.647857 | J26: =(G26/0.75)+0.3 -> 23.958 | K26: =(G26/0.8)+0.3 -> 22.479375
B27: 250-299 | C27: 250 | D27: 299 | E27: HVPSP4D | F27: 43.49 | G27: =F27*$G$9 -> 19.5705 | H27: =(G27/0.65)+0.3 -> 30.408462 | I27: =(G27/0.7)+0.3 -> 28.257857 | J27: =(G27/0.75)+0.3 -> 26.394 | K27: =(G27/0.8)+0.3 -> 24.763125
B28: 300-399 | C28: 300 | D28: 399 | E28: HVPSP4E | F28: 49.05 | G28: =F28*$G$9 -> 22.0725 | H28: =(G28/0.65)+0.3 -> 34.257692 | I28: =(G28/0.7)+0.3 -> 31.832143 | J28: =(G28/0.75)+0.3 -> 29.73 | K28: =(G28/0.8)+0.3 -> 27.890625
B29: 400-499 | C29: 400 | D29: 499 | E29: HVPSP4F | F29: 54.49 | G29: =F29*$G$9 -> 24.5205 | H29: =(G29/0.65)+0.3 -> 38.023846 | I29: =(G29/0.7)+0.3 -> 35.329286 | J29: =(G29/0.75)+0.3 -> 32.994 | K29: =(G29/0.8)+0.3 -> 30.950625
B30: 500-599 | C30: 500 | D30: 599 | E30: HVPSP4G | F30: 58.46 | G30: =F30*$G$9 -> 26.307 | H30: =(G30/0.65)+0.3 -> 40.772308 | I30: =(G30/0.7)+0.3 -> 37.881429 | J30: =(G30/0.75)+0.3 -> 35.376 | K30: =(G30/0.8)+0.3 -> 33.18375
B31: 600-699 | C31: 600 | D31: 699 | E31: HVPSP4H | F31: 62.52 | G31: =F31*$G$9 -> 28.134 | H31: =(G31/0.65)+0.3 -> 43.583077 | I31: =(G31/0.7)+0.3 -> 40.491429 | J31: =(G31/0.75)+0.3 -> 37.812 | K31: =(G31/0.8)+0.3 -> 35.4675
B32: 700-799 | C32: 700 | D32: 799 | E32: HVPSP4I | F32: 66.92 | G32: =F32*$G$9 -> 30.114 | H32: =(G32/0.65)+0.3 -> 46.629231 | I32: =(G32/0.7)+0.3 -> 43.32 | J32: =(G32/0.75)+0.3 -> 40.452 | K32: =(G32/0.8)+0.3 -> 37.9425
B33: 800-899 | C33: 800 | D33: 899 | E33: HVPSP4J | F33: 73.63 | G33: =F33*$G$9 -> 33.1335 | H33: =(G33/0.65)+0.3 -> 51.274615 | I33: =(G33/0.7)+0.3 -> 47.633571 | J33: =(G33/0.75)+0.3 -> 44.478 | K33: =(G33/0.8)+0.3 -> 41.716875
B34: 900-999 | C34: 900 | D34: 999 | E34: HVPSP4K | F34: 81.04 | G34: =F34*$G$9 -> 36.468 | H34: =(G34/0.65)+0.3 -> 56.404615 | I34: =(G34/0.7)+0.3 -> 52.397143 | J34: =(G34/0.75)+0.3 -> 48.924 | K34: =(G34/0.8)+0.3 -> 45.885
L42: montclair
L43: 0 | M43: 0
L44: 962-2ply | M44: 32
L45: F8V4-2424-GWB | M45: 13
L46: FP 200 | M46: 8
L47: FP-H13HEPA-2424115-WG | M47: 5
L48: HVP10241 | M48: 188
B49: MINIMUM: | L49: HVP16202 | M49: 8 | Q49: la palma
...

Sheet MR11 1
T1: List Price Sheet 6MR11-Z
S2: 46143
C3: AFC COST | D3: 35% Margin | E3: 30% Margin | F3: 25% Margin | T3: Section 6
T4: Product Bulletin 6 MR11
B7: The Z-Line Series MR-11
C9: 1 | M9: 2
B10: PART | C10: STANDARD | D10: LIST | E10: Multiplier | I10: CARTON | J10: CARTON | L10: PART | M10: STANDARD | N10: LIST | O10: Multiplier | S10: CARTON | T10: CARTON
B11: NUMBER | C11: SIZES | D11: PRICE | E11: 0.34 | F11: 35% Margin | G11: 30% Margin | H11: 25% Margin | I11: QUANTITY | J11: WEIGHT | L11: NUMBER | M11: SIZES | N11: PRICE | O11: 0.34 | P11: 35% Margin | Q11: 30% Margin | R11: 25% Margin | S11: QUANTITY | T11: WEIGHT
B12: M1110101 | C12: 10x10x1 | D12: 13.83 | E12: =D12*$E$11 -> 4.7022 | F12: =(E12/0.65)+0.3 -> 7.5341538 | G12: =(E12/0.7)+0.3 -> 7.0174286 | H12: =(E12/0.75)+0.3 -> 6.5696 | I12: 12 | J12: 3 LB. | L12: M1110202 | M12: 10x20x2 | N12: 14.98 | O12: =N12*$O$11 -> 5.0932 | P12: =(O12/0.65)+0.3 -> 8.1356923 | Q12: =(O12/0.7)+0.3 -> 7.576 | R12: =(O12/0.75)+0.3 -> 7.0909333 | S12: 12 | T12: 8 LB.
B13: M1110201 | C13: 10x20x1 | D13: 14.55 | E13: =D13*$E$11 -> 4.947 | F13: =(E13/0.65)+0.3 -> 7.9107692 | G13: =(E13/0.7)+0.3 -> 7.3671429 | H13: =(E13/0.75)+0.3 -> 6.896 | I13: 12 | J13: 5 LB. | L13: M1112122 | M13: 12x12x2 | N13: 15.48 | O13: =N13*$O$11 -> 5.2632 | P13: =(O13/0.65)+0.3 -> 8.3972308 | Q13: =(O13/0.7)+0.3 -> 7.8188571 | R13: =(O13/0.75)+0.3 -> 7.3176 | S13: 12 | T13: 6 LB.
B14: M1110241 | C14: 10x24x1 | D14: 21.25 | E14: =D14*$E$11 -> 7.225 | F14: =(E14/0.65)+0.3 -> 11.415385 | G14: =(E14/0.7)+0.3 -> 10.621429 | H14: =(E14/0.75)+0.3 -> 9.9333333 | I14: 12 | J14: 6 LB. | L14: M1112202 | M14: 12x20x2 | N14: 15.88 | O14: =N14*$O$11 -> 5.3992 | P14: =(O14/0.65)+0.3 -> 8.6064615 | Q14: =(O14/0.7)+0.3 -> 8.0131429 | R14: =(O14/0.75)+0.3 -> 7.4989333 | S14: 12 | T14: 9 LB.
B15: M1110301 | C15: 10x30x1 | D15: 21.75 | E15: =D15*$E$11 -> 7.395 | F15: =(E15/0.65)+0.3 -> 11.676923 | G15: =(E15/0.7)+0.3 -> 10.864286 | H15: =(E15/0.75)+0.3 -> 10.16 | I15: 12 | J15: 8 LB. | L15: M1112242 | M15: 12x24x2 | N15: 15.11 | O15: =N15*$O$11 -> 5.1374 | P15: =(O15/0.65)+0.3 -> 8.2036923 | Q15: =(O15/0.7)+0.3 -> 7.6391429 | R15: =(O15/0.75)+0.3 -> 7.1498667 | S15: 12 | T15: 11 LB.
B16: M1112121 | C16: 12x12x1 | D16: 15.71 | E16: =D16*$E$11 -> 5.3414 | F16: =(E16/0.65)+0.3 -> 8.5175385 | G16: =(E16/0.7)+0.3 -> 7.9305714 | H16: =(E16/0.75)+0.3 -> 7.4218667 | I16: 12 | J16: 4 LB. | L16: M1114202 | M16: 14x20x2 | N16: 15.48 | O16: =N16*$O$11 -> 5.2632 | P16: =(O16/0.65)+0.3 -> 8.3972308 | Q16: =(O16/0.7)+0.3 -> 7.8188571 | R16: =(O16/0.75)+0.3 -> 7.3176 | S16: 12 | T16: 11 LB.
B17: M1112201 | C17: 12x20x1 | D17: 14.98 | E17: =D17*$E$11 -> 5.0932 | F17: =(E17/0.65)+0.3 -> 8.1356923 | G17: =(E17/0.7)+0.3 -> 7.576 | H17: =(E17/0.75)+0.3 -> 7.0909333 | I17: 12 | J17: 6 LB. | L17: M1114252 | M17: 14x25x2 | N17: 16.81 | O17: =N17*$O$11 -> 5.7154 | P17: =(O17/0.65)+0.3 -> 9.0929231 | Q17: =(O17/0.7)+0.3 -> 8.4648571 | R17: =(O17/0.75)+0.3 -> 7.9205333 | S17: 12 | T17: 12 LB.
B18: M1112241 | C18: 12x24x1 | D18: 13.65 | E18: =D18*$E$11 -> 4.641 | F18: =(E18/0.65)+0.3 -> 7.44 | G18: =(E18/0.7)+0.3 -> 6.93 | H18: =(E18/0.75)+0.3 -> 6.488 | I18: 12 | J18: 7 LB. | L18: M1115202 | M18: 15x20x2 | N18: 15.98 | O18: =N18*$O$11 -> 5.4332 | P18: =(O18/0.65)+0.3 -> 8.6587692 | Q18: =(O18/0.7)+0.3 -> 8.0617143 | R18: =(O18/0.75)+0.3 -> 7.5442667 | S18: 12 | T18: 11 LB.
B19: M1112251 | C19: 12x25x1 | D19: 14.62 | E19: =D19*$E$11 -> 4.9708 | F19: =(E19/0.65)+0.3 -> 7.9473846 | G19: =(E19/0.7)+0.3 -> 7.4011429 | H19: =(E19/0.75)+0.3 -> 6.9277333 | I19: 12 | J19: 7 LB. | L19: M1116162 | M19: 16x16x2 | N19: 20.46 | O19: =N19*$O$11 -> 6.9564 | P19: =(O19/0.65)+0.3 -> 11.002154 | Q19: =(O19/0.7)+0.3 -> 10.237714 | R19: =(O19/0.75)+0.3 -> 9.5752 | S19: 12 | T19: 11 LB.
B20: M1112301 | C20: 12x30x1 | D20: 21.75 | E20: =D20*$E$11 -> 7.395 | F20: =(E20/0.65)+0.3 -> 11.676923 | G20: =(E20/0.7)+0.3 -> 10.864286 | H20: =(E20/0.75)+0.3 -> 10.16 | I20: 12 | J20: 8 LB. | L20: M1116202 | M20: 16x20x2 | N20: 15.32 | O20: =N20*$O$11 -> 5.2088 | P20: =(O20/0.65)+0.3 -> 8.3135385 | Q20: =(O20/0.7)+0.3 -> 7.7411429 | R20: =(O20/0.75)+0.3 -> 7.2450667 | S20: 12 | T20: 12 LB.
B21: M1114141 | C21: 14x14x1 | D21: 15.6 | E21: =D21*$E$11 -> 5.304 | F21: =(E21/0.65)+0.3 -> 8.46 | G21: =(E21/0.7)+0.3 -> 7.8771429 | H21: =(E21/0.75)+0.3 -> 7.372 | I21: 12 | J21: 5 LB. | L21: M1116242 | M21: 16x24x2 | N21: 19.7 | O21: =N21*$O$11 -> 6.698 | P21: =(O21/0.65)+0.3 -> 10.604615 | Q21: =(O21/0.7)+0.3 -> 9.8685714 | R21: =(O21/0.75)+0.3 -> 9.2306667 | S21: 12 | T21: 13 LB.
B22: M1114201 | C22: 14x20x1 | D22: 13.96 | E22: =D22*$E$11 -> 4.7464 | F22: =(E22/0.65)+0.3 -> 7.6021538 | G22: =(E22/0.7)+0.3 -> 7.0805714 | H22: =(E22/0.75)+0.3 -> 6.6285333 | I22: 12 | J22: 6 LB. | L22: M1116252 | M22: 16x25x2 | N22: 17.73 | O22: =N22*$O$11 -> 6.0282 | P22: =(O22/0.65)+0.3 -> 9.5741538 | Q22: =(O22/0.7)+0.3 -> 8.9117143 | R22: =(O22/0.75)+0.3 -> 8.3376 | S22: 12 | T22: 14 LB.
B23: M1114241 | C23: 14x24x1 | D23: 22.51 | E23: =D23*$E$11 -> 7.6534 | F23: =(E23/0.65)+0.3 -> 12.074462 | G23: =(E23/0.7)+0.3 -> 11.233429 | H23: =(E23/0.75)+0.3 -> 10.504533 | I23: 12 | J23: 7 LB. | L23: M1118182 | M23: 18x18x2 | N23: 24.82 | O23: =N23*$O$11 -> 8.4388 | P23: =(O23/0.65)+0.3 -> 13.282769 | Q23: =(O23/0.7)+0.3 -> 12.355429 | R23: =(O23/0.75)+0.3 -> 11.551733 | S23: 12 | T23: 12 LB.
... B32: M1116301 | C32: 16x30x1 | D32: 23.48 | E32: =D32*$E$11 -> 7.9832 | F32: =(E32/0.65)+0.3 -> 12.581846 | G32: =(E32/0.7)+0.3 -> 11.704571 | H32: =(E32/0.75)+0.3 -> 10.944267 | I32: 12 | J32: 10 LB. | L32: M1125252 | M32: 25x25x2 | N32: 27.39 | O32: =N32*$O$11 -> 9.3126 | P32: =(O32/0.65)+0.3 -> 14.627077 | Q32: =(O32/0.7)+0.3 -> 13.603714 | R32: =(O32/0.75)+0.3 -> 12.7168 | S32: 12 | T32: 20 LB.
B33: M1118181 | C33: 18x18x1 | D33: 21.75 | E33: =D33*$E$11 -> 7.395 | F33: =(E33/0.65)+0.3 -> 11.676923 | G33: =(E33/0.7)+0.3 -> 10.864286 | H33: =(E33/0.75)+0.3 -> 10.16 | I33: 12 | J33: 7 LB.
B34: M1118201 | C34: 18x20x1 | D34: 20.39 | E34: =D34*$E$11 -> 6.9326 | F34: =(E34/0.65)+0.3 -> 10.965538 | G34: =(E34/0.7)+0.3 -> 10.203714 | H34: =(E34/0.75)+0.3 -> 9.5434667 | I34: 12 | J34: 8 LB. | L34: Geo-Thermal Replacement Sizes
B35: M1118241 | C35: 18x24x1 | D35: 17.13 | E35: =D35*$E$11 -> 5.8242 | F35: =(E35/0.65)+0.3 -> 9.2603077 | G35: =(E35/0.7)+0.3 -> 8.6202857 | H35: =(E35/0.75)+0.3 -> 8.0656 | I35: 12 | J35: 9 LB. | L35: PART | M35: Actual | N35: LIST | O35: Multiplier | S35: CARTON | T35: CARTON
B36: M1118251 | C36: 18x25x1 | D36: 19.1 | E36: =D36*$E$11 -> 6.494 | F36: =(E36/0.65)+0.3 -> 10.290769 | G36: =(E36/0.7)+0.3 -> 9.5771429 | H36: =(E36/0.75)+0.3 -> 8.9586667 | I36: 12 | J36: 9 LB. | L36: NUMBER | M36: SIZES | N36: PRICE | O36: 0.511 | S36: QUANTITY | T36: WEIGHT
B37: M1118301 | C37: 18x30x1 | D37: 26 | E37: =D37*$E$11 -> 8.84 | F37: =(E37/0.65)+0.3 -> 13.9 | G37: =(E37/0.7)+0.3 -> 12.928571 | H37: =(E37/0.75)+0.3 -> 12.086667 | I37: 12 | J37: 11 LB. | L37: M1124282 | M37: 23-1/2 x 27-3/4 x 2 | N37: 41.71 | O37: =N37*$O$36 -> 21.31381 | P37: =(O37/0.65)+0.3 -> 33.090477 | Q37: =(O37/0.7)+0.3 -> 30.7483 | R37: =(O37/0.75)+0.3 -> 28.718413 | S37: 6 | T37: 14 LB.
B38: M1120201 | C38: 20x20x1 | D38: 14.9 | E38: =D38*$E$11 -> 5.066 | F38: =(E38/0.65)+0.3 -> 8.0938462 | G38: =(E38/0.7)+0.3 -> 7.5371429 | H38: =(E38/0.75)+0.3 -> 7.0546667 | I38: 12 | J38: 8 LB. | L38: M1128302 | M38: 27-3/4 x 29-3/8 x 2 | N38: 72.41 | O38: =N38*$O$36 -> 37.00151 | P38: =(O38/0.65)+0.3 -> 57.2254 | Q38: =(O38/0.7)+0.3 -> 53.1593 | R38: =(O38/0.75)+0.3 -> 49.635347 | S38: 6 | T38: 16 LB.
B39: M1120221 | C39: 20x22x1 | D39: 20.77 | E39: =D39*$E$11 -> 7.0618 | F39: =(E39/0.65)+0.3 -> 11.164308 | G39: =(E39/0.7)+0.3 -> 10.388286 | H39: =(E39/0.75)+0.3 -> 9.7157333 | I39: 12 | J39: 9 LB. | L39: M1130322 | M39: 29-3/8 x 31-3/4 x 2 | N39: 72.41 | O39: =N39*$O$36 -> 37.00151 | P39: =(O39/0.65)+0.3 -> 57.2254 | Q39: =(O39/0.7)+0.3 -> 53.1593 | R39: =(O39/0.75)+0.3 -> 49.635347 | S39: 6 | T39: 17 LB.
B40: M1120241 | C40: 20x24x1 | D40: 16.93 | E40: =D40*$E$11 -> 5.7562 | F40: =(E40/0.65)+0.3 -> 9.1556923 | G40: =(E40/0.7)+0.3 -> 8.5231429 | H40: =(E40/0.75)+0.3 -> 7.9749333 | I40: 12 | J40: 10 LB. | L40: M1130362 | M40: 29-3/8 x 35-3/4 x 2 | N40: 77.71 | O40: =N40*$O$36 -> 39.70981 | P40: =(O40/0.65)+0.3 -> 61.392015 | Q40: =(O40/0.7)+0.3 -> 57.0283 | R40: =(O40/0.75)+0.3 -> 53.246413 | S40: 6 | T40: 18 LB.
B41: M1120251 | C41: 20x25x1 | D41: 16.7 | E41: =D41*$E$11 -> 5.678 | F41: =(E41/0.65)+0.3 -> 9.0353846 | G41: =(E41/0.7)+0.3 -> 8.4114286 | H41: =(E41/0.75)+0.3 -> 7.8706667 | I41: 12 | J41: 10 LB.
B42: M1120301 | C42: 20x30x1 | D42: 22.38 | E42: =D42*$E$11 -> 7.6092 | F42: =(E42/0.65)+0.3 -> 12.006462 | G42: =(E42/0.7)+0.3 -> 11.170286 | H42: =(E42/0.75)+0.3 -> 10.4456 | I42: 12 | J42: 11 LB.
B43: M1122221 | C43: 22x22x1 | D43: 24.17 | E43: =D43*$E$11 -> 8.2178 | F43: =(E43/0.65)+0.3 -> 12.942769 | G43: =(E43/0.7)+0.3 -> 12.039714 | H43: =(E43/0.75)+0.3 -> 11.257067 | I43: 12 | J43: 9 LB.
B44: M1124241 | C44: 24x24x1 | D44: 19.41 | E44: =D44*$E$11 -> 6.5994 | F44: =(E44/0.65)+0.3 -> 10.452923 | G44: =(E44/0.7)+0.3 -> 9.7277143 | H44: =(E44/0.75)+0.3 -> 9.0992 | I44: 12 | J44: 11 LB.
B45: M1124301 | C45: 24x30x1 | D45: 28.67 | E45: =D45*$E$11 -> 9.7478 | F45: =(E45/0.65)+0.3 -> 15.296615 | G45: =(E45/0.7)+0.3 -> 14.225429 | H45: =(E45/0.75)+0.3 -> 13.297067 | I45: 12 | J45: 14 LB.
B46: M1125251 | C46: 25x25x1 | D46: 23.24 | E46: =D46*$E$11 -> 7.9016 | F46: =(E46/0.65)+0.3 -> 12.456308 | G46: =(E46/0.7)+0.3 -> 11.588 | H46: =(E46/0.75)+0.3 -> 10.835467 | I46: 12 | J46: 13 LB.
C49: 4 | M49: 6
B50: PART | C50: STANDARD | D50: LIST | E50: Multiplier | I50: CARTON | J50: CARTON | L50: PART | M50: STANDARD | N50: LIST | O50: Multiplier | S50: CARTON | T50: CARTON
B51: NUMBER | C51: SIZES | D51: PRICE | E51: 0.34 | F51: 35% Margin | G51: 30% Margin | H51: 25% Margin | I51: QUANTITY | J51: WEIGHT | L51: NUMBER | M51: SIZES | N51: PRICE | O51: 0.34 | P51: 35% Margin | Q51: 30% Margin | R51: 25% Margin | S51: QUANTITY | T51: WEIGHT
B52: M1112244 | C52: 12x24x4 | D52: 27.3 | E52: =D52*$E$51 -> 9.282 | F52: =(E52/0.65)+0.3 -> 14.58 | G52: =(E52/0.7)+0.3 -> 13.56 | H52: =(E52/0.75)+0.3 -> 12.676 | I52: 6 | J52: 9 LB. | L52: M1112246 | M52: 12x24x6 | N52: 38.3 | O52: =N52*$O$51 -> 13.022 | P52: =(O52/0.65)+0.3 -> 20.333846 | Q52: =(O52/0.7)+0.3 -> 18.902857 | R52: =(O52/0.75)+0.3 -> 17.662667 | S52: 4 | T52: 9 LB.
B53: M1116204 | C53: 16x20x4 | D53: 26.78 | E53: =D53*$E$51 -> 9.1052 | F53: =(E53/0.65)+0.3 -> 14.308 | G53: =(E53/0.7)+0.3 -> 13.307429 | H53: =(E53/0.75)+0.3 -> 12.440267 | I53: 6 | J53: 10 LB. | L53: M1116206 | M53: 16x20x6 | N53: 37.96 | O53: =N53*$O$51 -> 12.9064 | P53: =(O53/0.65)+0.3 -> 20.156 | Q53: =(O53/0.7)+0.3 -> 18.737714 | R53: =(O53/0.75)+0.3 -> 17.508533 | S53: 4 | T53: 11 LB.
...

Sheet MR11 2
L2: SIZES | M2: H | N2: L | O2: W | P2: TOTAL | Q2: PRICE 1" | R2: PRICE 2" | S2: PRICE 4" | V2: PRICE 1" | W2: PRICE 2" | X2: PRICE 4"
C3: AFC COST | D3: 35% Margin | E3: 30% Margin | F3: 25% Margin | M3: 16 | N3: 24 | O3: 1 | P3: =M3*N3 -> 384 | Q3: =_xlfn.XLOOKUP($M$3*$N$3, $D$11:$D$20, $I$11:$I$20, $I$11, -1) -> 22.760415 | R3: =_xlfn.XLOOKUP($M$3*$N$3, $D$11:$D$20, $Q$11:$Q$20, $Q$11, -1) -> 26.573262 | S3: =_xlfn.XLOOKUP($M$3*$N$3, $D$11:$D$20, $Y$11:$Y$20, $Y$11, -1) -> 50.417308 | T3: 0.35 | V3: =IF(OR(AND($M$3>28, $N$3>28), $M$3>35, $N$3>35),_xlfn.XLOOKUP(($M$3*$N$3)/2, $D$11:$D$20, $I$11:$I$20, $I$11, -1) * 2,"N/A") -> N/A | W3: {=IF(OR(AND($M$3>28, $N$3>28), $M$3>35, $N$3>35),_xlfn.XLOOKUP(($M$3*$N$3)/2, $D$11:$D$20, Q$11:$Q$20, $Q$11, -1) * 2,"N/A")} -> N/A | X3: =IF(OR(AND($M$3>28, $N$3>28), $M$3>35, $N$3>35),_xlfn.XLOOKUP(($M$3*$N$3)/2, $D$11:$D$20, $Y$11:$Y$20, $Y$11, -1) * 2,"N/A") -> N/A | Y3: 0.35
